Workbook

Sheet Vật tư hàng hóa
A1: Mã VTHH (*) | B1: Tên VTHH (*) | C1: ĐVT chính | D1: Số lượng tồn tối thiểu | E1: Giá bán cố định | F1: Giá bán 1 | G1: Giá bán 2 | H1: Giá bán 3 | I1: Số lượng từ | J1: Số lượng đến | K1: Loại chiết khấu | L1: % hoặc số tiền CK | M1: Đơn vị tính | N1: Đơn giá mua | O1: ĐVT chuyển đổi | P1: Tỷ lệ chuyển đổi | Q1: Phép tính | R1: Giá bán cố định theo ĐVT chuyển đổi | S1: Giá bán 1 theo ĐVT chuyển đổi | T1: Giá bán 2 theo ĐVT chuyển đổi | U1: Giá bán 3 theo ĐVT chuyển đổi | V1: Mã VTHH lắp ráp/ tháo dỡ | W1: Đơn vị tính VTHH lắp ráp/ tháo dỡ | X1: Số lượng VTHH lắp ráp/ tháo dỡ | Y1: Đơn giá VTHH lắp ráp/ tháo dỡ | Z1: Thành tiền VTHH lắp ráp/ tháo dỡ
A2: Bánh Khoai Tây xá 4kg | B2: Bánh Khoai Tây xá 4kg | C2: kg | D2: 0 | E2: 58850 | O2: Thùng | P2: 4 | Q2: * | R2: 235400 | S2: 0 | T2: 0 | U2: 0
A3: Kẹo Dẻo Bóc Vỏ vị Xoài 1kg PC | B3: Kẹo Dẻo Bóc Vỏ vị Xoài 1kg PC | C3: Gói | D3: 0 | E3: 91300
A4: VP26_01 | B4: Nước T-REXX Oishi Túi 180ml (5 bịch/T) | C4: Bịch | D4: 0 | E4: 28160.007 | O4: Thùng | P4: 5 | Q4: * | R4: 140800.04 | S4: 0 | T4: 0 | U4: 0
A5: VP26_02 | B5: Bánh snack Oishi 2K (10 bịch/bao) | C5: Bịch | D5: 0 | E5: 15248.077 | O5: Bao | P5: 10 | Q5: * | R5: 152480.77 | S5: 0 | T5: 0 | U5: 0
A6: VP26_03 | B6: Nước ÉP THẠCH Suso (48ly) | C6: Ly | D6: 0 | E6: 3941.6688 | O6: Thùng | P6: 48 | Q6: * | R6: 189200.1 | S6: 0 | T6: 0 | U6: 0
A7: VP26_04 | B7: Thạch Suso Tam Giác TÚI LƯỚI (62 cái) | C7: Cái | D7: 0 | E7: 585.4838 | O7: Gói | P7: 62 | Q7: * | R7: 36299.997 | S7: 0 | T7: 0 | U7: 0
A8: VP26_05 | B8: Bánh Choco PN TÚI 216g (12 cái/túi) | C8: Cái | D8: 0 | E8: 1714.5876 | O8: Túi | P8: 12 | Q8: * | R8: 20575.051 | S8: 0 | T8: 0 | U8: 0
A9: VP26_06 | B9: Kẹo Cao Su Dinos 500g ( 69 viên) | C9: Viên | D9: 0 | E9: 832.5286 | O9: Gói | P9: 69 | Q9: * | R9: 57444.473 | S9: 0 | T9: 0 | U9: 0
A10: VP26_07 | B10: Bánh Lương Khô 370g PC | C10: Gói | D10: 0 | E10: 32568.462
A11: VP26_08 | B11: Kẹo Oishi 85 gram (80 gói/T) | C11: Gói | D11: 0 | E11: 5456 | O11: Thùng | P11: 80 | Q11: * | R11: 436480 | S11: 0 | T11: 0 | U11: 0
A12: VP26_09 | B12: Bánh Pillows Oishi 2K (10 bịch/T) | C12: Bịch | D12: 0 | E12: 15981.425 | O12: Thùng | P12: 10 | Q12: * | R12: 159814.25 | S12: 0 | T12: 0 | U12: 0
A13: VP26_10 | B13: Bánh snack Oishi 5K (8 bịch/bao) | C13: Bịch | D13: 0 | E13: 38500.011 | O13: Bao | P13: 8 | Q13: * | R13: 308000.09 | S13: 0 | T13: 0 | U13: 0
A14: VP26_11 | B14: Bánh snack Oishi LỚN 10K (6 bịch/bao) | C14: Bịch | D14: 0 | E14: 74910 | O14: Bao | P14: 6 | Q14: * | R14: 449460 | S14: 0 | T14: 0 | U14: 0
A15: VP26_12 | B15: Thạch SUSO Tam Giác LỚN (62 cái) | C15: Cái | D15: 0 | E15: 550 | O15: Gói | P15: 62 | Q15: * | R15: 34100 | S15: 0 | T15: 0 | U15: 0
A16: VP26_13 | B16: Bánh Chấm 330g PC (12 cái) | C16: Cái | D16: 0 | E16: 2383.3307 | O16: Gói | P16: 12 | Q16: * | R16: 28599.968 | S16: 0 | T16: 0 | U16: 0
A17: VP26_14 | B17: Sôcôla Trân châu 130g PC | C17: Gói | D17: 0 | E17: 14575
A18: VP26_15 | B18: Bánh CreamO 85g - CÂY LỚN | C18: Cây | D18: 0 | E18: 7512.3548
A19: VP26_16 | B19: Snack URC loại 5K (8 bịch / bao) | C19: Bịch | D19: 0 | E19: 39600 | O19: Bao | P19: 8 | Q19: * | R19: 316800 | S19: 0 | T19: 0 | U19: 0
A20: VP26_17 | B20: Bánh bông lan tam giác nguyên chất vị dâu | C20: Cái | O20: Chiếc | P20: 1 | Q20: * | R20: 0 | S20: 0 | T20: 0 | U20: 0
O21: Thùng | P21: 10 | Q21: * | R21: 0 | S21: 0 | T21: 0 | U21: 0
A22: VP26_18 | B22: Bánh bông lan tam giác nguyên chất vị lá non lúa mạch | C22: Cái | D22: 0 | E22: 15562.8 | O22: Thùng | P22: 10 | Q22: * | R22: 155628 | S22: 0 | T22: 0 | U22: 0
A23: VP26_19 | B23: Bánh bông lan tam giác nguyên chất vị socola | C23: Cái | D23: 0 | E23: 15562.8 | O23: Thùng | P23: 10 | Q23: * | R23: 155628 | S23: 0 | T23: 0 | U23: 0
A24: VP26_20 | B24: Bánh bông lan tam giác nguyên chất vị phô mai | C24: Cái | D24: 0 | E24: 15562.8 | O24: Thùng | P24: 10 | Q24: * | R24: 155628 | S24: 0 | T24: 0 | U24: 0
A25: VP26_21 | B25: Bánh mỳ bơ sữa cuộn nhiều lớp hiệu Gold 100 (2,5kg /carton) | C25: Cái | D25: 0 | E25: 3825.36 | O25: Thùng | P25: 50 | Q25: * | R25: 191268 | S25: 0 | T25: 0 | U25: 0
A26: VP26_22 | B26: Thạch rau câu Long Hải BS Canxi (500gr/túi x 12 túi/thùng) | C26: Túi | D26: 0 | E26: 22000.089 | O26: Thùng | P26: 12 | Q26: * | R26: 264001.07 | S26: 0 | T26: 0 | U26: 0
A27: VP26_23 | B27: Thạch Caramel Lapatie túi - 16g (400g/túi x 12 túi/thùng) - NT | C27: Túi | D27: 0 | E27: 15400 | O27: Thùng | P27: 12 | Q27: * | R27: 184800 | S27: 0 | T27: 0 | U27: 0
A28: VP26_24 | B28: Nước rau câu Đào (95gr/cốc x 100cốc/thùng) - NT | C28: Cốc | D28: 0 | E28: 1815 | O28: Thùng | P28: 100 | Q28: * | R28: 181500 | S28: 0 | T28: 0 | U28: 0
A29: VP26_25 | B29: Nước rau câu Cam (95gr/cốc x 100cốc/thùng) - NT | C29: Cốc | D29: 0 | E29: 1815 | O29: Thùng | P29: 100 | Q29: * | R29: 181500 | S29: 0 | T29: 0 | U29: 0
A30: VP26_26 | B30: Bánh mì toast ngàn lớp sữa bò (milk thousand layer toast) | C30: Cái | D30: 0 | E30: 6682.5 | O30: Thùng | P30: 24 | Q30: * | R30: 160380 | S30: 0 | T30: 0 | U30: 0
A31: VP26_27 | B31: Bánh vị sữa chua | C31: Cái | D31: 0 | E31: 6088.5 | O31: Thùng | P31: 24 | Q31: * | R31: 146124 | S31: 0 | T31: 0 | U31: 0
A32: VP26_28 | B32: Cà Phê Phố HỘP sữa đá (10 gói/Hộp) | C32: Gói | D32: 0 | E32: 4972 | O32: Hộp | P32: 10 | Q32: * | R32: 49720 | S32: 0 | T32: 0 | U32: 0
A33: VP26_29 | B33: Nui 5K Hoàng Thắng 50g (100 gói/T) | C33: Gói | D33: 0 | E33: 4551.25 | O33: Thùng | P33: 100 | Q33: * | R33: 455125 | S33: 0 | T33: 0 | U33: 0
... A37: VP26_33 | B37: Thạch SUSO Tam Giác 330g Nhỏ (27 cái) | C37: Cái | D37: 0 | E37: 631.481 | O37: Gói | P37: 27 | Q37: * | R37: 17049.986 | S37: 0 | T37: 0 | U37: 0
A38: VP26_34 | B38: Bánh Phồng Tôm ĐẶC BIỆT 200g | C38: Hộp | D38: 0 | E38: 17600
A39: VP26_35 | B39: Bánh Que Oishi Akiko 1K (10 bịch/T) | C39: Bịch | D39: 0 | E39: 15707.994 | O39: Thùng | P39: 10 | Q39: * | R39: 157079.94 | S39: 0 | T39: 0 | U39: 0
A40: VP26_36 | B40: Trà Cúc 2 (ba đồng tiền) | C40: Lon | D40: 0 | E40: 56100
A41: VP26_37 | B41: Bánh quy hộp THIẾC VUÔNG 400g | C41: Hộp | D41: 0 | E41: 47300
A42: VP26_38 | B42: Coke 320ml - Coca Lon LỚN | C42: Lon | D42: 0 | E42: 9166.6716 | O42: Thùng | P42: 24 | Q42: * | R42: 220000.12 | S42: 0 | T42: 0 | U42: 0
A43: VP26_39 | B43: Bánh XỐP Kem Cẩm Huê 5kg | C43: Cái | D43: 0 | E43: 9487.5 | O43: Thùng | P43: 24 | Q43: * | R43: 227700 | S43: 0 | T43: 0 | U43: 0
...

Sheet T4.2026
A1: Mã VTHH (*) | B1: Tên VTHH (*) | C1: ĐVT chính | D1: Giá bán cố định | E1: Tồn gốc (ẩn) | F1: Tồn hiện tại
A2: Bánh Khoai Tây xá 4kg | B2: Bánh Khoai Tây xá 4kg | C2: kg | D2: 58850 | E2: 4 | F2: =IF(A2="","",E2-SUMIF('SL bán theo ngày'!$A$9:$A$82,A2,'SL bán theo ngày'!$AJ$9:$AJ$82)) -> 0
A3: VP26_01 | B3: Nước T-REXX Oishi Túi 180ml (5 bịch/T) | C3: Bịch | D3: 28160.007 | E3: 25 | F3: =IF(A3="","",E3-SUMIF('SL bán theo ngày'!$A$9:$A$82,A3,'SL bán theo ngày'!$AJ$9:$AJ$82)) -> 0
A4: VP26_02 | B4: Bánh snack Oishi 2K (10 bịch/bao) | C4: Bịch | D4: 15248.077 | E4: 280 | F4: =IF(A4="","",E4-SUMIF('SL bán theo ngày'!$A$9:$A$82,A4,'SL bán theo ngày'!$AJ$9:$AJ$82)) -> 15
A5: VP26_10 | B5: Bánh snack Oishi 5K (8 bịch/bao) | C5: Bịch | D5: 38500.011 | E5: 8 | F5: =IF(A5="","",E5-SUMIF('SL bán theo ngày'!$A$9:$A$82,A5,'SL bán theo ngày'!$AJ$9:$AJ$82)) -> 1
A6: VP26_13 | B6: Bánh Chấm 330g PC (12 cái) | C6: Cái | D6: 2383.3307 | E6: 120 | F6: =IF(A6="","",E6-SUMIF('SL bán theo ngày'!$A$9:$A$82,A6,'SL bán theo ngày'!$AJ$9:$AJ$82)) -> 8
A7: VP26_32 | B7: Thạch miếng nhỏ Suso LƯỚI 800g (62 cái) | C7: Cái | D7: 550 | E7: 372 | F7: =IF(A7="","",E7-SUMIF('SL bán theo ngày'!$A$9:$A$82,A7,'SL bán theo ngày'!$AJ$9:$AJ$82)) -> 21
A8: VP26_40 | B8: Coke 300ml - Coca Chai Nhí 5K | C8: Chai | D8: 4285.4429 | E8: 24 | F8: =IF(A8="","",E8-SUMIF('SL bán theo ngày'!$A$9:$A$82,A8,'SL bán theo ngày'!$AJ$9:$AJ$82)) -> 2
A9: VP26_41 | B9: Đậu phộng Oishi 1K (20 dây/T) | C9: Dây | D9: 7636.53 | E9: 20 | F9: =IF(A9="","",E9-SUMIF('SL bán theo ngày'!$A$9:$A$82,A9,'SL bán theo ngày'!$AJ$9:$AJ$82)) -> 2
A10: VP26_43 | B10: Thạch SUSO Cây Dài (24 cái) | C10: Cái | D10: 1375 | E10: 432 | F10: =IF(A10="","",E10-SUMIF('SL bán theo ngày'!$A$9:$A$82,A10,'SL bán theo ngày'!$AJ$9:$AJ$82)) -> 26
A11: VP26_45 | B11: Mì Vàng Enaak 30g (24 gói/Hộp) | C11: Gói | D11: 5500 | E11: 144 | F11: =IF(A11="","",E11-SUMIF('SL bán theo ngày'!$A$9:$A$82,A11,'SL bán theo ngày'!$AJ$9:$AJ$82)) -> 9
A12: VP26_46 | B12: Nước ÉP THẠCH Suso (48 ly) | C12: Ly | D12: 3941.6656 | E12: 480 | F12: =IF(A12="","",E12-SUMIF('SL bán theo ngày'!$A$9:$A$82,A12,'SL bán theo ngày'!$AJ$9:$AJ$82)) -> 29
A13: VP26_47 | B13: Kẹo Cao Su Dinos 500g (69 viên) | C13: Viên | D13: 828.9848 | E13: 759 | F13: =IF(A13="","",E13-SUMIF('SL bán theo ngày'!$A$9:$A$82,A13,'SL bán theo ngày'!$AJ$9:$AJ$82)) -> 46
... A15: VP26_50 | B15: Nước Túi Oishi (10 túi x 5 bịch / T) | C15: Túi | D15: 2560 | E15: 500 | F15: =IF(A15="","",E15-SUMIF('SL bán theo ngày'!$A$9:$A$82,A15,'SL bán theo ngày'!$AJ$9:$AJ$82)) -> 30
F26: =IF(A26="","",E26-SUMIF('SL bán theo ngày'!$A$9:$A$82,A26,'SL bán theo ngày'!$AJ$9:$AJ$82))
F27: =IF(A27="","",E27-SUMIF('SL bán theo ngày'!$A$9:$A$82,A27,'SL bán theo ngày'!$AJ$9:$AJ$82))
F28: =IF(A28="","",E28-SUMIF('SL bán theo ngày'!$A$9:$A$82,A28,'SL bán theo ngày'!$AJ$9:$AJ$82))
F29: =IF(A29="","",E29-SUMIF('SL bán theo ngày'!$A$9:$A$82,A29,'SL bán theo ngày'!$AJ$9:$AJ$82))
F30: =IF(A30="","",E30-SUMIF('SL bán theo ngày'!$A$9:$A$82,A30,'SL bán theo ngày'!$AJ$9:$AJ$82))
F31: =IF(A31="","",E31-SUMIF('SL bán theo ngày'!$A$9:$A$82,A31,'SL bán theo ngày'!$AJ$9:$AJ$82))
F32: =IF(A32="","",E32-SUMIF('SL bán theo ngày'!$A$9:$A$82,A32,'SL bán theo ngày'!$AJ$9:$AJ$82))
F33: =IF(A33="","",E33-SUMIF('SL bán theo ngày'!$A$9:$A$82,A33,'SL bán theo ngày'!$AJ$9:$AJ$82))
F34: =IF(A34="","",E34-SUMIF('SL bán theo ngày'!$A$9:$A$82,A34,'SL bán theo ngày'!$AJ$9:$AJ$82))
F35: =IF(A35="","",E35-SUMIF('SL bán theo ngày'!$A$9:$A$82,A35,'SL bán theo ngày'!$AJ$9:$AJ$82))
F36: =IF(A36="","",E36-SUMIF('SL bán theo ngày'!$A$9:$A$82,A36,'SL bán theo ngày'!$AJ$9:$AJ$82))
F37: =IF(A37="","",E37-SUMIF('SL bán theo ngày'!$A$9:$A$82,A37,'SL bán theo ngày'!$AJ$9:$AJ$82))
... F75: =IF(A75="","",E75-SUMIF('SL bán theo ngày'!$A$9:$A$82,A75,'SL bán theo ngày'!$AJ$9:$AJ$82))

Sheet Phân bổ bán hàng
A1: PHÂN BỔ BÁN HÀNG THEO TỔNG TIỀN
A2: Nhập tổng tiền tại ô B3. Mọi mặt hàng có dữ liệu trong T4.2026 đều được đảo vị trí; phân bổ ngẫu nhiên ưu tiên tồn nhiều. Mặt hàng cuối tự cân chênh lệch.
A3: Tổng tiền cần phân bổ | B3: 415000 | D3: Tổng đã phân bổ | E3: =SUM(G7:G80) -> 415998 | G3: Chênh lệch | H3: =E3-B3 -> 998
A4: Trạng thái | B4: =IF(B3<=0,"Hãy nhập tổng tiền",IF(ABS(H3)<=500,"Đã khớp gần đúng","Còn chênh lệch do giới hạn tồn kho/đơn giá")) -> Còn chênh lệch do giới hạn tồn kho/đơn giá
A6: Mã VTHH | B6: Tên VTHH | C6: ĐVT | D6: Đơn giá | E6: Tồn trước bán | F6: SL bán | G6: Thành tiền | H6: Tồn sau bán | I6: Dòng nguồn | J6: Khóa đảo
A7: {=IF(ROWS($A$7:A7)>COUNTIF('T4.2026'!$A$2:$A$75,"?*"),"",INDEX('T4.2026'!A:A,INDEX($I$7:$I$80,MATCH(SMALL($J$7:$J$80,ROWS($A$7:A7)),$J$7:$J$80,0))))} -> VP26_40 | B7: {=IF($A7="","",INDEX('T4.2026'!B:B,INDEX($I$7:$I$80,MATCH(SMALL($J$7:$J$80,ROWS($A$7:A7)),$J$7:$J$80,0))))} -> Coke 300ml - Coca Chai Nhí 5K | C7: {=IF($A7="","",INDEX('T4.2026'!C:C,INDEX($I$7:$I$80,MATCH(SMALL($J$7:$J$80,ROWS($A$7:A7)),$J$7:$J$80,0))))} -> Chai | D7: {=IF($A7="","",ROUND(INDEX('T4.2026'!D:D,INDEX($I$7:$I$80,MATCH(SMALL($J$7:$J$80,ROWS($A$7:A7)),$J$7:$J$80,0))),0))} -> 4285 | E7: {=IF($A7="","",INDEX('T4.2026'!E:E,INDEX($I$7:$I$80,MATCH(SMALL($J$7:$J$80,ROWS($A$7:A7)),$J$7:$J$80,0))))} -> 24 | F7: {=IF($A7="","",IF(ROWS($A$7:A7)=COUNTIF('T4.2026'!$A$2:$A$75,"?*"),MIN(E7,MAX(0,ROUND(($B$3-SUM($G$6:G6))/D7,0))),MIN(E7,MAX(0,ROUNDDOWN(($B$3*(E7*(0.5+MOD(ABS(SIN($B$3*0.001+ROW()*12.9898))*43758.5453,1)))/SUMPRODUCT($E$7:$E$80,0.5+MOD(ABS(SIN($B$3*0.001+ROW($E$7:$E$80)*12.9898))*43758.5453,1)))/D7,0)))))} -> 0 | G7: =IF($A7="","",F7*D7) -> 0 | H7: =IF($A7="","",E7-F7) -> 24 | I7: =IF(ROWS($I$7:I7)<=COUNTIF('T4.2026'!$A$2:$A$75,"?*"),ROWS($I$7:I7)+1,"") -> 2 | J7: =IF(I7="",1E+99,MOD(ABS(SIN($B$3*0.001+I7*12.9898))*43758.5453,1)) -> 0.82708851
A8: {=IF(ROWS($A$7:A8)>COUNTIF('T4.2026'!$A$2:$A$75,"?*"),"",INDEX('T4.2026'!A:A,INDEX($I$7:$I$80,MATCH(SMALL($J$7:$J$80,ROWS($A$7:A8)),$J$7:$J$80,0))))} -> VP26_43 | B8: {=IF($A8="","",INDEX('T4.2026'!B:B,INDEX($I$7:$I$80,MATCH(SMALL($J$7:$J$80,ROWS($A$7:A8)),$J$7:$J$80,0))))} -> Thạch SUSO Cây Dài (24 cái) | C8: {=IF($A8="","",INDEX('T4.2026'!C:C,INDEX($I$7:$I$80,MATCH(SMALL($J$7:$J$80,ROWS($A$7:A8)),$J$7:$J$80,0))))} -> Cái | D8: {=IF($A8="","",ROUND(INDEX('T4.2026'!D:D,INDEX($I$7:$I$80,MATCH(SMALL($J$7:$J$80,ROWS($A$7:A8)),$J$7:$J$80,0))),0))} -> 1375 | E8: {=IF($A8="","",INDEX('T4.2026'!E:E,INDEX($I$7:$I$80,MATCH(SMALL($J$7:$J$80,ROWS($A$7:A8)),$J$7:$J$80,0))))} -> 432 | F8: {=IF($A8="","",IF(ROWS($A$7:A8)=COUNTIF('T4.2026'!$A$2:$A$75,"?*"),MIN(E8,MAX(0,ROUND(($B$3-SUM($G$6:G7))/D8,0))),MIN(E8,MAX(0,ROUNDDOWN(($B$3*(E8*(0.5+MOD(ABS(SIN($B$3*0.001+ROW()*12.9898))*43758.5453,1)))/SUMPRODUCT($E$7:$E$80,0.5+MOD(ABS(SIN($B$3*0.001+ROW($E$7:$E$80)*12.9898))*43758.5453,1)))/D8,0)))))} -> 27 | G8: =IF($A8="","",F8*D8) -> 37125 | H8: =IF($A8="","",E8-F8) -> 405 | I8: =IF(ROWS($I$7:I8)<=COUNTIF('T4.2026'!$A$2:$A$75,"?*"),ROWS($I$7:I8)+1,"") -> 3 | J8: =IF(I8="",1E+99,MOD(ABS(SIN($B$3*0.001+I8*12.9898))*43758.5453,1)) -> 0.66858763
A9: {=IF(ROWS($A$7:A9)>COUNTIF('T4.2026'!$A$2:$A$75,"?*"),"",INDEX('T4.2026'!A:A,INDEX($I$7:$I$80,MATCH(SMALL($J$7:$J$80,ROWS($A$7:A9)),$J$7:$J$80,0))))} -> VP26_13 | B9: {=IF($A9="","",INDEX('T4.2026'!B:B,INDEX($I$7:$I$80,MATCH(SMALL($J$7:$J$80,ROWS($A$7:A9)),$J$7:$J$80,0))))} -> Bánh Chấm 330g PC (12 cái) | C9: {=IF($A9="","",INDEX('T4.2026'!C:C,INDEX($I$7:$I$80,MATCH(SMALL($J$7:$J$80,ROWS($A$7:A9)),$J$7:$J$80,0))))} -> Cái | D9: {=IF($A9="","",ROUND(INDEX('T4.2026'!D:D,INDEX($I$7:$I$80,MATCH(SMALL($J$7:$J$80,ROWS($A$7:A9)),$J$7:$J$80,0))),0))} -> 2383 | E9: {=IF($A9="","",INDEX('T4.2026'!E:E,INDEX($I$7:$I$80,MATCH(SMALL($J$7:$J$80,ROWS($A$7:A9)),$J$7:$J$80,0))))} -> 120 | F9: {=IF($A9="","",IF(ROWS($A$7:A9)=COUNTIF('T4.2026'!$A$2:$A$75,"?*"),MIN(E9,MAX(0,ROUND(($B$3-SUM($G$6:G8))/D9,0))),MIN(E9,MAX(0,ROUNDDOWN(($B$3*(E9*(0.5+MOD(ABS(SIN($B$3*0.001+ROW()*12.9898))*43758.5453,1)))/SUMPRODUCT($E$7:$E$80,0.5+MOD(ABS(SIN($B$3*0.001+ROW($E$7:$E$80)*12.9898))*43758.5453,1)))/D9,0)))))} -> 12 | G9: =IF($A9="","",F9*D9) -> 28596 | H9: =IF($A9="","",E9-F9) -> 108 | I9: =IF(ROWS($I$7:I9)<=COUNTIF('T4.2026'!$A$2:$A$75,"?*"),ROWS($I$7:I9)+1,"") -> 4 | J9: =IF(I9="",1E+99,MOD(ABS(SIN($B$3*0.001+I9*12.9898))*43758.5453,1)) -> 0.7877366
A10: {=IF(ROWS($A$7:A10)>COUNTIF('T4.2026'!$A$2:$A$75,"?*"),"",INDEX('T4.2026'!A:A,INDEX($I$7:$I$80,MATCH(SMALL($J$7:$J$80,ROWS($A$7:A10)),$J$7:$J$80,0))))} -> VP26_47 | B10: {=IF($A10="","",INDEX('T4.2026'!B:B,INDEX($I$7:$I$80,MATCH(SMALL($J$7:$J$80,ROWS($A$7:A10)),$J$7:$J$80,0))))} -> Kẹo Cao Su Dinos 500g (69 viên) | C10: {=IF($A10="","",INDEX('T4.2026'!C:C,INDEX($I$7:$I$80,MATCH(SMALL($J$7:$J$80,ROWS($A$7:A10)),$J$7:$J$80,0))))} -> Viên | D10: {=IF($A10="","",ROUND(INDEX('T4.2026'!D:D,INDEX($I$7:$I$80,MATCH(SMALL($J$7:$J$80,ROWS($A$7:A10)),$J$7:$J$80,0))),0))} -> 829 | E10: {=IF($A10="","",INDEX('T4.2026'!E:E,INDEX($I$7:$I$80,MATCH(SMALL($J$7:$J$80,ROWS($A$7:A10)),$J$7:$J$80,0))))} -> 759 | F10: {=IF($A10="","",IF(ROWS($A$7:A10)=COUNTIF('T4.2026'!$A$2:$A$75,"?*"),MIN(E10,MAX(0,ROUND(($B$3-SUM($G$6:G9))/D10,0))),MIN(E10,MAX(0,ROUNDDOWN(($B$3*(E10*(0.5+MOD(ABS(SIN($B$3*0.001+ROW()*12.9898))*43758.5453,1)))/SUMPRODUCT($E$7:$E$80,0.5+MOD(ABS(SIN($B$3*0.001+ROW($E$7:$E$80)*12.9898))*43758.5453,1)))/D10,0)))))} -> 88 | G10: =IF($A10="","",F10*D10) -> 72952 | H10: =IF($A10="","",E10-F10) -> 671 | I10: =IF(ROWS($I$7:I10)<=COUNTIF('T4.2026'!$A$2:$A$75,"?*"),ROWS($I$7:I10)+1,"") -> 5 | J10: =IF(I10="",1E+99,MOD(ABS(SIN($B$3*0.001+I10*12.9898))*43758.5453,1)) -> 0.1573599
A11: {=IF(ROWS($A$7:A11)>COUNTIF('T4.2026'!$A$2:$A$75,"?*"),"",INDEX('T4.2026'!A:A,INDEX($I$7:$I$80,MATCH(SMALL($J$7:$J$80,ROWS($A$7:A11)),$J$7:$J$80,0))))} -> VP26_49 | B11: {=IF($A11="","",INDEX('T4.2026'!B:B,INDEX($I$7:$I$80,MATCH(SMALL($J$7:$J$80,ROWS($A$7:A11)),$J$7:$J$80,0))))} -> Bánh Mứt Dâu Xá 4kg PC | C11: {=IF($A11="","",INDEX('T4.2026'!C:C,INDEX($I$7:$I$80,MATCH(SMALL($J$7:$J$80,ROWS($A$7:A11)),$J$7:$J$80,0))))} -> kg | D11: {=IF($A11="","",ROUND(INDEX('T4.2026'!D:D,INDEX($I$7:$I$80,MATCH(SMALL($J$7:$J$80,ROWS($A$7:A11)),$J$7:$J$80,0))),0))} -> 61875 | E11: {=IF($A11="","",INDEX('T4.2026'!E:E,INDEX($I$7:$I$80,MATCH(SMALL($J$7:$J$80,ROWS($A$7:A11)),$J$7:$J$80,0))))} -> 4 | F11: {=IF($A11="","",IF(ROWS($A$7:A11)=COUNTIF('T4.2026'!$A$2:$A$75,"?*"),MIN(E11,MAX(0,ROUND(($B$3-SUM($G$6:G10))/D11,0))),MIN(E11,MAX(0,ROUNDDOWN(($B$3*(E11*(0.5+MOD(ABS(SIN($B$3*0.001+ROW()*12.9898))*43758.5453,1)))/SUMPRODUCT($E$7:$E$80,0.5+MOD(ABS(SIN($B$3*0.001+ROW($E$7:$E$80)*12.9898))*43758.5453,1)))/D11,0)))))} -> 0 | G11: =IF($A11="","",F11*D11) -> 0 | H11: =IF($A11="","",E11-F11) -> 4 | I11: =IF(ROWS($I$7:I11)<=COUNTIF('T4.2026'!$A$2:$A$75,"?*"),ROWS($I$7:I11)+1,"") -> 6 | J11: =IF(I11="",1E+99,MOD(ABS(SIN($B$3*0.001+I11*12.9898))*43758.5453,1)) -> 0.11586067
A12: {=IF(ROWS($A$7:A12)>COUNTIF('T4.2026'!$A$2:$A$75,"?*"),"",INDEX('T4.2026'!A:A,INDEX($I$7:$I$80,MATCH(SMALL($J$7:$J$80,ROWS($A$7:A12)),$J$7:$J$80,0))))} -> VP26_10 | B12: {=IF($A12="","",INDEX('T4.2026'!B:B,INDEX($I$7:$I$80,MATCH(SMALL($J$7:$J$80,ROWS($A$7:A12)),$J$7:$J$80,0))))} -> Bánh snack Oishi 5K (8 bịch/bao) | C12: {=IF($A12="","",INDEX('T4.2026'!C:C,INDEX($I$7:$I$80,MATCH(SMALL($J$7:$J$80,ROWS($A$7:A12)),$J$7:$J$80,0))))} -> Bịch | D12: {=IF($A12="","",ROUND(INDEX('T4.2026'!D:D,INDEX($I$7:$I$80,MATCH(SMALL($J$7:$J$80,ROWS($A$7:A12)),$J$7:$J$80,0))),0))} -> 38500 | E12: {=IF($A12="","",INDEX('T4.2026'!E:E,INDEX($I$7:$I$80,MATCH(SMALL($J$7:$J$80,ROWS($A$7:A12)),$J$7:$J$80,0))))} -> 8 | F12: {=IF($A12="","",IF(ROWS($A$7:A12)=COUNTIF('T4.2026'!$A$2:$A$75,"?*"),MIN(E12,MAX(0,ROUND(($B$3-SUM($G$6:G11))/D12,0))),MIN(E12,MAX(0,ROUNDDOWN(($B$3*(E12*(0.5+MOD(ABS(SIN($B$3*0.001+ROW()*12.9898))*43758.5453,1)))/SUMPRODUCT($E$7:$E$80,0.5+MOD(ABS(SIN($B$3*0.001+ROW($E$7:$E$80)*12.9898))*43758.5453,1)))/D12,0)))))} -> 0 | G12: =IF($A12="","",F12*D12) -> 0 | H12: =IF($A12="","",E12-F12) -> 8 | I12: =IF(ROWS($I$7:I12)<=COUNTIF('T4.2026'!$A$2:$A$75,"?*"),ROWS($I$7:I12)+1,"") -> 7 | J12: =IF(I12="",1E+99,MOD(ABS(SIN($B$3*0.001+I12*12.9898))*43758.5453,1)) -> 0.29687772
A13: {=IF(ROWS($A$7:A13)>COUNTIF('T4.2026'!$A$2:$A$75,"?*"),"",INDEX('T4.2026'!A:A,INDEX($I$7:$I$80,MATCH(SMALL($J$7:$J$80,ROWS($A$7:A13)),$J$7:$J$80,0))))} -> VP26_32 | B13: {=IF($A13="","",INDEX('T4.2026'!B:B,INDEX($I$7:$I$80,MATCH(SMALL($J$7:$J$80,ROWS($A$7:A13)),$J$7:$J$80,0))))} -> Thạch miếng nhỏ Suso LƯỚI 800g (62 cái) | C13: {=IF($A13="","",INDEX('T4.2026'!C:C,INDEX($I$7:$I$80,MATCH(SMALL($J$7:$J$80,ROWS($A$7:A13)),$J$7:$J$80,0))))} -> Cái | D13: {=IF($A13="","",ROUND(INDEX('T4.2026'!D:D,INDEX($I$7:$I$80,MATCH(SMALL($J$7:$J$80,ROWS($A$7:A13)),$J$7:$J$80,0))),0))} -> 550 | E13: {=IF($A13="","",INDEX('T4.2026'!E:E,INDEX($I$7:$I$80,MATCH(SMALL($J$7:$J$80,ROWS($A$7:A13)),$J$7:$J$80,0))))} -> 372 | F13: {=IF($A13="","",IF(ROWS($A$7:A13)=COUNTIF('T4.2026'!$A$2:$A$75,"?*"),MIN(E13,MAX(0,ROUND(($B$3-SUM($G$6:G12))/D13,0))),MIN(E13,MAX(0,ROUNDDOWN(($B$3*(E13*(0.5+MOD(ABS(SIN($B$3*0.001+ROW()*12.9898))*43758.5453,1)))/SUMPRODUCT($E$7:$E$80,0.5+MOD(ABS(SIN($B$3*0.001+ROW($E$7:$E$80)*12.9898))*43758.5453,1)))/D13,0)))))} -> 69 | G13: =IF($A13="","",F13*D13) -> 37950 | H13: =IF($A13="","",E13-F13) -> 303 | I13: =IF(ROWS($I$7:I13)<=COUNTIF('T4.2026'!$A$2:$A$75,"?*"),ROWS($I$7:I13)+1,"") -> 8 | J13: =IF(I13="",1E+99,MOD(ABS(SIN($B$3*0.001+I13*12.9898))*43758.5453,1)) -> 0.034344031
A14: {=IF(ROWS($A$7:A14)>COUNTIF('T4.2026'!$A$2:$A$75,"?*"),"",INDEX('T4.2026'!A:A,INDEX($I$7:$I$80,MATCH(SMALL($J$7:$J$80,ROWS($A$7:A14)),$J$7:$J$80,0))))} -> VP26_45 | B14: {=IF($A14="","",INDEX('T4.2026'!B:B,INDEX($I$7:$I$80,MATCH(SMALL($J$7:$J$80,ROWS($A$7:A14)),$J$7:$J$80,0))))} -> Mì Vàng Enaak 30g (24 gói/Hộp) | C14: {=IF($A14="","",INDEX('T4.2026'!C:C,INDEX($I$7:$I$80,MATCH(SMALL($J$7:$J$80,ROWS($A$7:A14)),$J$7:$J$80,0))))} -> Gói | D14: {=IF($A14="","",ROUND(INDEX('T4.2026'!D:D,INDEX($I$7:$I$80,MATCH(SMALL($J$7:$J$80,ROWS($A$7:A14)),$J$7:$J$80,0))),0))} -> 5500 | E14: {=IF($A14="","",INDEX('T4.2026'!E:E,INDEX($I$7:$I$80,MATCH(SMALL($J$7:$J$80,ROWS($A$7:A14)),$J$7:$J$80,0))))} -> 144 | F14: {=IF($A14="","",IF(ROWS($A$7:A14)=COUNTIF('T4.2026'!$A$2:$A$75,"?*"),MIN(E14,MAX(0,ROUND(($B$3-SUM($G$6:G13))/D14,0))),MIN(E14,MAX(0,ROUNDDOWN(($B$3*(E14*(0.5+MOD(ABS(SIN($B$3*0.001+ROW()*12.9898))*43758.5453,1)))/SUMPRODUCT($E$7:$E$80,0.5+MOD(ABS(SIN($B$3*0.001+ROW($E$7:$E$80)*12.9898))*43758.5453,1)))/D14,0)))))} -> 2 | G14: =IF($A14="","",F14*D14) -> 11000 | H14: =IF($A14="","",E14-F14) -> 142 | I14: =IF(ROWS($I$7:I14)<=COUNTIF('T4.2026'!$A$2:$A$75,"?*"),ROWS($I$7:I14)+1,"") -> 9 | J14: =IF(I14="",1E+99,MOD(ABS(SIN($B$3*0.001+I14*12.9898))*43758.5453,1)) -> 0.97822076
A15: {=IF(ROWS($A$7:A15)>COUNTIF('T4.2026'!$A$2:$A$75,"?*"),"",INDEX('T4.2026'!A:A,INDEX($I$7:$I$80,MATCH(SMALL($J$7:$J$80,ROWS($A$7:A15)),$J$7:$J$80,0))))} -> VP26_50 | B15: {=IF($A15="","",INDEX('T4.2026'!B:B,INDEX($I$7:$I$80,MATCH(SMALL($J$7:$J$80,ROWS($A$7:A15)),$J$7:$J$80,0))))} -> Nước Túi Oishi (10 túi x 5 bịch / T) | C15: {=IF($A15="","",INDEX('T4.2026'!C:C,INDEX($I$7:$I$80,MATCH(SMALL($J$7:$J$80,ROWS($A$7:A15)),$J$7:$J$80,0))))} -> Túi | D15: {=IF($A15="","",ROUND(INDEX('T4.2026'!D:D,INDEX($I$7:$I$80,MATCH(SMALL($J$7:$J$80,ROWS($A$7:A15)),$J$7:$J$80,0))),0))} -> 2560 | E15: {=IF($A15="","",INDEX('T4.2026'!E:E,INDEX($I$7:$I$80,MATCH(SMALL($J$7:$J$80,ROWS($A$7:A15)),$J$7:$J$80,0))))} -> 500 | F15: {=IF($A15="","",IF(ROWS($A$7:A15)=COUNTIF('T4.2026'!$A$2:$A$75,"?*"),MIN(E15,MAX(0,ROUND(($B$3-SUM($G$6:G14))/D15,0))),MIN(E15,MAX(0,ROUNDDOWN(($B$3*(E15*(0.5+MOD(ABS(SIN($B$3*0.001+ROW()*12.9898))*43758.5453,1)))/SUMPRODUCT($E$7:$E$80,0.5+MOD(ABS(SIN($B$3*0.001+ROW($E$7:$E$80)*12.9898))*43758.5453,1)))/D15,0)))))} -> 36 | G15: =IF($A15="","",F15*D15) -> 92160 | H15: =IF($A15="","",E15-F15) -> 464 | I15: =IF(ROWS($I$7:I15)<=COUNTIF('T4.2026'!$A$2:$A$75,"?*"),ROWS($I$7:I15)+1,"") -> 10 | J15: =IF(I15="",1E+99,MOD(ABS(SIN($B$3*0.001+I15*12.9898))*43758.5453,1)) -> 0.092562993
A16: {=IF(ROWS($A$7:A16)>COUNTIF('T4.2026'!$A$2:$A$75,"?*"),"",INDEX('T4.2026'!A:A,INDEX($I$7:$I$80,MATCH(SMALL($J$7:$J$80,ROWS($A$7:A16)),$J$7:$J$80,0))))} -> VP26_01 | B16: {=IF($A16="","",INDEX('T4.2026'!B:B,INDEX($I$7:$I$80,MATCH(SMALL($J$7:$J$80,ROWS($A$7:A16)),$J$7:$J$80,0))))} -> Nước T-REXX Oishi Túi 180ml (5 bịch/T) | C16: {=IF($A16="","",INDEX('T4.2026'!C:C,INDEX($I$7:$I$80,MATCH(SMALL($J$7:$J$80,ROWS($A$7:A16)),$J$7:$J$80,0))))} -> Bịch | D16: {=IF($A16="","",ROUND(INDEX('T4.2026'!D:D,INDEX($I$7:$I$80,MATCH(SMALL($J$7:$J$80,ROWS($A$7:A16)),$J$7:$J$80,0))),0))} -> 28160 | E16: {=IF($A16="","",INDEX('T4.2026'!E:E,INDEX($I$7:$I$80,MATCH(SMALL($J$7:$J$80,ROWS($A$7:A16)),$J$7:$J$80,0))))} -> 25 | F16: {=IF($A16="","",IF(ROWS($A$7:A16)=COUNTIF('T4.2026'!$A$2:$A$75,"?*"),MIN(E16,MAX(0,ROUND(($B$3-SUM($G$6:G15))/D16,0))),MIN(E16,MAX(0,ROUNDDOWN(($B$3*(E16*(0.5+MOD(ABS(SIN($B$3*0.001+ROW()*12.9898))*43758.5453,1)))/SUMPRODUCT($E$7:$E$80,0.5+MOD(ABS(SIN($B$3*0.001+ROW($E$7:$E$80)*12.9898))*43758.5453,1)))/D16,0)))))} -> 0 | G16: =IF($A16="","",F16*D16) -> 0 | H16: =IF($A16="","",E16-F16) -> 25 | I16: =IF(ROWS($I$7:I16)<=COUNTIF('T4.2026'!$A$2:$A$75,"?*"),ROWS($I$7:I16)+1,"") -> 11 | J16: =IF(I16="",1E+99,MOD(ABS(SIN($B$3*0.001+I16*12.9898))*43758.5453,1)) -> 0.39012435
A17: {=IF(ROWS($A$7:A17)>COUNTIF('T4.2026'!$A$2:$A$75,"?*"),"",INDEX('T4.2026'!A:A,INDEX($I$7:$I$80,MATCH(SMALL($J$7:$J$80,ROWS($A$7:A17)),$J$7:$J$80,0))))} -> VP26_46 | B17: {=IF($A17="","",INDEX('T4.2026'!B:B,INDEX($I$7:$I$80,MATCH(SMALL($J$7:$J$80,ROWS($A$7:A17)),$J$7:$J$80,0))))} -> Nước ÉP THẠCH Suso (48 ly) | C17: {=IF($A17="","",INDEX('T4.2026'!C:C,INDEX($I$7:$I$80,MATCH(SMALL($J$7:$J$80,ROWS($A$7:A17)),$J$7:$J$80,0))))} -> Ly | D17: {=IF($A17="","",ROUND(INDEX('T4.2026'!D:D,INDEX($I$7:$I$80,MATCH(SMALL($J$7:$J$80,ROWS($A$7:A17)),$J$7:$J$80,0))),0))} -> 3942 | E17: {=IF($A17="","",INDEX('T4.2026'!E:E,INDEX($I$7:$I$80,MATCH(SMALL($J$7:$J$80,ROWS($A$7:A17)),$J$7:$J$80,0))))} -> 480 | F17: {=IF($A17="","",IF(ROWS($A$7:A17)=COUNTIF('T4.2026'!$A$2:$A$75,"?*"),MIN(E17,MAX(0,ROUND(($B$3-SUM($G$6:G16))/D17,0))),MIN(E17,MAX(0,ROUNDDOWN(($B$3*(E17*(0.5+MOD(ABS(SIN($B$3*0.001+ROW()*12.9898))*43758.5453,1)))/SUMPRODUCT($E$7:$E$80,0.5+MOD(ABS(SIN($B$3*0.001+ROW($E$7:$E$80)*12.9898))*43758.5453,1)))/D17,0)))))} -> 21 | G17: =IF($A17="","",F17*D17) -> 82782 | H17: =IF($A17="","",E17-F17) -> 459 | I17: =IF(ROWS($I$7:I17)<=COUNTIF('T4.2026'!$A$2:$A$75,"?*"),ROWS($I$7:I17)+1,"") -> 12 | J17: =IF(I17="",1E+99,MOD(ABS(SIN($B$3*0.001+I17*12.9898))*43758.5453,1)) -> 0.76875801
A18: {=IF(ROWS($A$7:A18)>COUNTIF('T4.2026'!$A$2:$A$75,"?*"),"",INDEX('T4.2026'!A:A,INDEX($I$7:$I$80,MATCH(SMALL($J$7:$J$80,ROWS($A$7:A18)),$J$7:$J$80,0))))} -> VP26_02 | B18: {=IF($A18="","",INDEX('T4.2026'!B:B,INDEX($I$7:$I$80,MATCH(SMALL($J$7:$J$80,ROWS($A$7:A18)),$J$7:$J$80,0))))} -> Bánh snack Oishi 2K (10 bịch/bao) | C18: {=IF($A18="","",INDEX('T4.2026'!C:C,INDEX($I$7:$I$80,MATCH(SMALL($J$7:$J$80,ROWS($A$7:A18)),$J$7:$J$80,0))))} -> Bịch | D18: {=IF($A18="","",ROUND(INDEX('T4.2026'!D:D,INDEX($I$7:$I$80,MATCH(SMALL($J$7:$J$80,ROWS($A$7:A18)),$J$7:$J$80,0))),0))} -> 15248 | E18: {=IF($A18="","",INDEX('T4.2026'!E:E,INDEX($I$7:$I$80,MATCH(SMALL($J$7:$J$80,ROWS($A$7:A18)),$J$7:$J$80,0))))} -> 280 | F18: {=IF($A18="","",IF(ROWS($A$7:A18)=COUNTIF('T4.2026'!$A$2:$A$75,"?*"),MIN(E18,MAX(0,ROUND(($B$3-SUM($G$6:G17))/D18,0))),MIN(E18,MAX(0,ROUNDDOWN(($B$3*(E18*(0.5+MOD(ABS(SIN($B$3*0.001+ROW()*12.9898))*43758.5453,1)))/SUMPRODUCT($E$7:$E$80,0.5+MOD(ABS(SIN($B$3*0.001+ROW($E$7:$E$80)*12.9898))*43758.5453,1)))/D18,0)))))} -> 1 | G18: =IF($A18="","",F18*D18) -> 15248 | H18: =IF($A18="","",E18-F18) -> 279 | I18: =IF(ROWS($I$7:I18)<=COUNTIF('T4.2026'!$A$2:$A$75,"?*"),ROWS($I$7:I18)+1,"") -> 13 | J18: =IF(I18="",1E+99,MOD(ABS(SIN($B$3*0.001+I18*12.9898))*43758.5453,1)) -> 0.12468694
... A80: {=IF(ROWS($A$7:A80)>COUNTIF('T4.2026'!$A$2:$A$75,"?*"),"",INDEX('T4.2026'!A:A,INDEX($I$7:$I$80,MATCH(SMALL($J$7:$J$80,ROWS($A$7:A80)),$J$7:$J$80,0))))} | B80: {=IF($A80="","",INDEX('T4.2026'!B:B,INDEX($I$7:$I$80,MATCH(SMALL($J$7:$J$80,ROWS($A$7:A80)),$J$7:$J$80,0))))} | C80: {=IF($A80="","",INDEX('T4.2026'!C:C,INDEX($I$7:$I$80,MATCH(SMALL($J$7:$J$80,ROWS($A$7:A80)),$J$7:$J$80,0))))} | D80: {=IF($A80="","",ROUND(INDEX('T4.2026'!D:D,INDEX($I$7:$I$80,MATCH(SMALL($J$7:$J$80,ROWS($A$7:A80)),$J$7:$J$80,0))),0))} | E80: {=IF($A80="","",INDEX('T4.2026'!E:E,INDEX($I$7:$I$80,MATCH(SMALL($J$7:$J$80,ROWS($A$7:A80)),$J$7:$J$80,0))))} | F80: {=IF($A80="","",IF(ROWS($A$7:A80)=COUNTIF('T4.2026'!$A$2:$A$75,"?*"),MIN(E80,MAX(0,ROUND(($B$3-SUM($G$6:G79))/D80,0))),MIN(E80,MAX(0,ROUNDDOWN(($B$3*(E80*(0.5+MOD(ABS(SIN($B$3*0.001+ROW()*12.9898))*43758.5453,1)))/SUMPRODUCT($E$7:$E$80,0.5+MOD(ABS(SIN($B$3*0.001+ROW($E$7:$E$80)*12.9898))*43758.5453,1)))/D80,0)))))} | G80: =IF($A80="","",F80*D80) | H80: =IF($A80="","",E80-F80) | I80: =IF(ROWS($I$7:I80)<=COUNTIF('T4.2026'!$A$2:$A$75,"?*"),ROWS($I$7:I80)+1,"") | J80: =IF(I80="",1E+99,MOD(ABS(SIN($B$3*0.001+I80*12.9898))*43758.5453,1)) -> 1e+99

Sheet BAO CAO BAN HANG
A1: BÁO CÁO CHI TIẾT SỐ LƯỢNG BÁN THEO NGÀY
A2: DOANH THU THÁNG | B2: 11000000 | C2: ĐÃ PHÂN BỔ | E2: ='SL bán theo ngày'!D2 -> 10999796 | G2: CHÊNH LỆCH | I2: ='SL bán theo ngày'!F2 -> -204
A3: THÁNG PHÂN BỔ | B3: 5 | C3: BIÊN ĐỘ TỐI ĐA | E3: 0.01 | G3: MÓN / NGÀY | I3: ='SL bán theo ngày'!F3 -> 11–13 món
A5: CHỈ TIÊU THEO NGÀY | C5: ='SL bán theo ngày'!F8 -> 1 | D5: ='SL bán theo ngày'!G8 -> 2 | E5: ='SL bán theo ngày'!H8 -> 3 | F5: ='SL bán theo ngày'!I8 -> 4 | G5: ='SL bán theo ngày'!J8 -> 5 | H5: ='SL bán theo ngày'!K8 -> 0 | I5: ='SL bán theo ngày'!L8 -> 0 | J5: ='SL bán theo ngày'!M8 -> 0 | ... AF5: ='SL bán theo ngày'!AI8 -> 0 | AJ5: TỔNG BÁN THÁNG
A6: Tổng số chủng loại bán | C6: ='SL bán theo ngày'!F84 -> 14 | D6: ='SL bán theo ngày'!G84 -> 13 | E6: ='SL bán theo ngày'!H84 -> 13 | F6: ='SL bán theo ngày'!I84 -> 13 | G6: ='SL bán theo ngày'!J84 -> 14 | H6: ='SL bán theo ngày'!K84 -> 0 | I6: ='SL bán theo ngày'!L84 -> 0 | J6: ='SL bán theo ngày'!M84 -> 0 | ... AF6: ='SL bán theo ngày'!AI84 -> 0
A7: Tổng số lượng bán | C7: ='SL bán theo ngày'!F85 -> 599 | D7: ='SL bán theo ngày'!G85 -> 598 | E7: ='SL bán theo ngày'!H85 -> 596 | F7: ='SL bán theo ngày'!I85 -> 595 | G7: ='SL bán theo ngày'!J85 -> 594 | H7: ='SL bán theo ngày'!K85 -> 0 | I7: ='SL bán theo ngày'!L85 -> 0 | J7: ='SL bán theo ngày'!M85 -> 0 | ... AF7: ='SL bán theo ngày'!AI85 -> 0
A8: Tổng tiền bán | C8: ='SL bán theo ngày'!F86 -> 2226118 | D8: ='SL bán theo ngày'!G86 -> 2198669 | E8: ='SL bán theo ngày'!H86 -> 2163150 | F8: ='SL bán theo ngày'!I86 -> 2192892 | G8: ='SL bán theo ngày'!J86 -> 2218967 | H8: ='SL bán theo ngày'!K86 -> 0 | I8: ='SL bán theo ngày'!L86 -> 0 | J8: ='SL bán theo ngày'!M86 -> 0 | ... AF8: ='SL bán theo ngày'!AI86 -> 0 | AJ8: ='SL bán theo ngày'!AJ86 -> 10999796
A9: CHI TIẾT SẢN LƯỢNG BÁN HÀNG NGÀY
A10: MÃ VTHH | B10: TÊN VTHH | C10: =C5 -> 1 | D10: =D5 -> 2 | E10: =E5 -> 3 | F10: =F5 -> 4 | G10: =G5 -> 5 | H10: =H5 -> 0 | I10: =I5 -> 0 | J10: =J5 -> 0 | ... AF10: =AF5 -> 0 | AG10: ĐVT | AH10: ĐƠN GIÁ | AI10: TỒN GỐC | AJ10: TỔNG SL BÁN | AK10: TỒN CUỐI
A11: {=IF(ROWS($A$11:$A11)<=COUNTIF('SL bán theo ngày'!$A$9:$A$82,"?*"),INDEX('SL bán theo ngày'!A$9:A$82,ROWS($A$11:$A11)),"")} -> Bánh Khoai Tây xá 4kg | B11: {=IF(ROWS($A$11:$A11)<=COUNTIF('SL bán theo ngày'!$A$9:$A$82,"?*"),INDEX('SL bán theo ngày'!B$9:B$82,ROWS($A$11:$A11)),"")} -> Bánh Khoai Tây xá 4kg | C11: {=IF(ROWS($A$11:$A11)<=COUNTIF('SL bán theo ngày'!$A$9:$A$82,"?*"),INDEX('SL bán theo ngày'!F$9:F$82,ROWS($A$11:$A11)),"")} -> 1 | D11: {=IF(ROWS($A$11:$A11)<=COUNTIF('SL bán theo ngày'!$A$9:$A$82,"?*"),INDEX('SL bán theo ngày'!G$9:G$82,ROWS($A$11:$A11)),"")} -> 1 | E11: {=IF(ROWS($A$11:$A11)<=COUNTIF('SL bán theo ngày'!$A$9:$A$82,"?*"),INDEX('SL bán theo ngày'!H$9:H$82,ROWS($A$11:$A11)),"")} -> 0 | F11: {=IF(ROWS($A$11:$A11)<=COUNTIF('SL bán theo ngày'!$A$9:$A$82,"?*"),INDEX('SL bán theo ngày'!I$9:I$82,ROWS($A$11:$A11)),"")} -> 1 | G11: {=IF(ROWS($A$11:$A11)<=COUNTIF('SL bán theo ngày'!$A$9:$A$82,"?*"),INDEX('SL bán theo ngày'!J$9:J$82,ROWS($A$11:$A11)),"")} -> 1 | H11: {=IF(ROWS($A$11:$A11)<=COUNTIF('SL bán theo ngày'!$A$9:$A$82,"?*"),INDEX('SL bán theo ngày'!K$9:K$82,ROWS($A$11:$A11)),"")} | I11: {=IF(ROWS($A$11:$A11)<=COUNTIF('SL bán theo ngày'!$A$9:$A$82,"?*"),INDEX('SL bán theo ngày'!L$9:L$82,ROWS($A$11:$A11)),"")} | J11: {=IF(ROWS($A$11:$A11)<=COUNTIF('SL bán theo ngày'!$A$9:$A$82,"?*"),INDEX('SL bán theo ngày'!M$9:M$82,ROWS($A$11:$A11)),"")} | ... AF11: {=IF(ROWS($A$11:$A11)<=COUNTIF('SL bán theo ngày'!$A$9:$A$82,"?*"),INDEX('SL bán theo ngày'!AI$9:AI$82,ROWS($A$11:$A11)),"")} | AG11: {=IF(ROWS($A$11:$A11)<=COUNTIF('SL bán theo ngày'!$A$9:$A$82,"?*"),INDEX('SL bán theo ngày'!C$9:C$82,ROWS($A$11:$A11)),"")} -> kg | AH11: {=IF(ROWS($A$11:$A11)<=COUNTIF('SL bán theo ngày'!$A$9:$A$82,"?*"),INDEX('SL bán theo ngày'!D$9:D$82,ROWS($A$11:$A11)),"")} -> 58850 | AI11: {=IF(ROWS($A$11:$A11)<=COUNTIF('SL bán theo ngày'!$A$9:$A$82,"?*"),INDEX('SL bán theo ngày'!E$9:E$82,ROWS($A$11:$A11)),"")} -> 4 | AJ11: {=IF(ROWS($A$11:$A11)<=COUNTIF('SL bán theo ngày'!$A$9:$A$82,"?*"),INDEX('SL bán theo ngày'!AJ$9:AJ$82,ROWS($A$11:$A11)),"")} -> 4 | AK11: {=IF(ROWS($A$11:$A11)<=COUNTIF('SL bán theo ngày'!$A$9:$A$82,"?*"),INDEX('SL bán theo ngày'!AK$9:AK$82,ROWS($A$11:$A11)),"")} -> 0
A12: {=IF(ROWS($A$11:$A12)<=COUNTIF('SL bán theo ngày'!$A$9:$A$82,"?*"),INDEX('SL bán theo ngày'!A$9:A$82,ROWS($A$11:$A12)),"")} -> VP26_01 | B12: {=IF(ROWS($A$11:$A12)<=COUNTIF('SL bán theo ngày'!$A$9:$A$82,"?*"),INDEX('SL bán theo ngày'!B$9:B$82,ROWS($A$11:$A12)),"")} -> Nước T-REXX Oishi Túi 180ml (5 bịch/T) | C12: {=IF(ROWS($A$11:$A12)<=COUNTIF('SL bán theo ngày'!$A$9:$A$82,"?*"),INDEX('SL bán theo ngày'!F$9:F$82,ROWS($A$11:$A12)),"")} -> 5 | D12: {=IF(ROWS($A$11:$A12)<=COUNTIF('SL bán theo ngày'!$A$9:$A$82,"?*"),INDEX('SL bán theo ngày'!G$9:G$82,ROWS($A$11:$A12)),"")} -> 5 | E12: {=IF(ROWS($A$11:$A12)<=COUNTIF('SL bán theo ngày'!$A$9:$A$82,"?*"),INDEX('SL bán theo ngày'!H$9:H$82,ROWS($A$11:$A12)),"")} -> 5 | F12: {=IF(ROWS($A$11:$A12)<=COUNTIF('SL bán theo ngày'!$A$9:$A$82,"?*"),INDEX('SL bán theo ngày'!I$9:I$82,ROWS($A$11:$A12)),"")} -> 5 | G12: {=IF(ROWS($A$11:$A12)<=COUNTIF('SL bán theo ngày'!$A$9:$A$82,"?*"),INDEX('SL bán theo ngày'!J$9:J$82,ROWS($A$11:$A12)),"")} -> 5 | H12: {=IF(ROWS($A$11:$A12)<=COUNTIF('SL bán theo ngày'!$A$9:$A$82,"?*"),INDEX('SL bán theo ngày'!K$9:K$82,ROWS($A$11:$A12)),"")} | I12: {=IF(ROWS($A$11:$A12)<=COUNTIF('SL bán theo ngày'!$A$9:$A$82,"?*"),INDEX('SL bán theo ngày'!L$9:L$82,ROWS($A$11:$A12)),"")} | J12: {=IF(ROWS($A$11:$A12)<=COUNTIF('SL bán theo ngày'!$A$9:$A$82,"?*"),INDEX('SL bán theo ngày'!M$9:M$82,ROWS($A$11:$A12)),"")} | ... AF12: {=IF(ROWS($A$11:$A12)<=COUNTIF('SL bán theo ngày'!$A$9:$A$82,"?*"),INDEX('SL bán theo ngày'!AI$9:AI$82,ROWS($A$11:$A12)),"")} | AG12: {=IF(ROWS($A$11:$A12)<=COUNTIF('SL bán theo ngày'!$A$9:$A$82,"?*"),INDEX('SL bán theo ngày'!C$9:C$82,ROWS($A$11:$A12)),"")} -> Bịch | AH12: {=IF(ROWS($A$11:$A12)<=COUNTIF('SL bán theo ngày'!$A$9:$A$82,"?*"),INDEX('SL bán theo ngày'!D$9:D$82,ROWS($A$11:$A12)),"")} -> 28160 | AI12: {=IF(ROWS($A$11:$A12)<=COUNTIF('SL bán theo ngày'!$A$9:$A$82,"?*"),INDEX('SL bán theo ngày'!E$9:E$82,ROWS($A$11:$A12)),"")} -> 25 | AJ12: {=IF(ROWS($A$11:$A12)<=COUNTIF('SL bán theo ngày'!$A$9:$A$82,"?*"),INDEX('SL bán theo ngày'!AJ$9:AJ$82,ROWS($A$11:$A12)),"")} -> 25 | AK12: {=IF(ROWS($A$11:$A12)<=COUNTIF('SL bán theo ngày'!$A$9:$A$82,"?*"),INDEX('SL bán theo ngày'!AK$9:AK$82,ROWS($A$11:$A12)),"")} -> 0
A13: {=IF(ROWS($A$11:$A13)<=COUNTIF('SL bán theo ngày'!$A$9:$A$82,"?*"),INDEX('SL bán theo ngày'!A$9:A$82,ROWS($A$11:$A13)),"")} -> VP26_02 | B13: {=IF(ROWS($A$11:$A13)<=COUNTIF('SL bán theo ngày'!$A$9:$A$82,"?*"),INDEX('SL bán theo ngày'!B$9:B$82,ROWS($A$11:$A13)),"")} -> Bánh snack Oishi 2K (10 bịch/bao) | C13: {=IF(ROWS($A$11:$A13)<=COUNTIF('SL bán theo ngày'!$A$9:$A$82,"?*"),INDEX('SL bán theo ngày'!F$9:F$82,ROWS($A$11:$A13)),"")} -> 53 | D13: {=IF(ROWS($A$11:$A13)<=COUNTIF('SL bán theo ngày'!$A$9:$A$82,"?*"),INDEX('SL bán theo ngày'!G$9:G$82,ROWS($A$11:$A13)),"")} -> 53 | E13: {=IF(ROWS($A$11:$A13)<=COUNTIF('SL bán theo ngày'!$A$9:$A$82,"?*"),INDEX('SL bán theo ngày'!H$9:H$82,ROWS($A$11:$A13)),"")} -> 53 | F13: {=IF(ROWS($A$11:$A13)<=COUNTIF('SL bán theo ngày'!$A$9:$A$82,"?*"),INDEX('SL bán theo ngày'!I$9:I$82,ROWS($A$11:$A13)),"")} -> 53 | G13: {=IF(ROWS($A$11:$A13)<=COUNTIF('SL bán theo ngày'!$A$9:$A$82,"?*"),INDEX('SL bán theo ngày'!J$9:J$82,ROWS($A$11:$A13)),"")} -> 53 | H13: {=IF(ROWS($A$11:$A13)<=COUNTIF('SL bán theo ngày'!$A$9:$A$82,"?*"),INDEX('SL bán theo ngày'!K$9:K$82,ROWS($A$11:$A13)),"")} | I13: {=IF(ROWS($A$11:$A13)<=COUNTIF('SL bán theo ngày'!$A$9:$A$82,"?*"),INDEX('SL bán theo ngày'!L$9:L$82,ROWS($A$11:$A13)),"")} | J13: {=IF(ROWS($A$11:$A13)<=COUNTIF('SL bán theo ngày'!$A$9:$A$82,"?*"),INDEX('SL bán theo ngày'!M$9:M$82,ROWS($A$11:$A13)),"")} | ... AF13: {=IF(ROWS($A$11:$A13)<=COUNTIF('SL bán theo ngày'!$A$9:$A$82,"?*"),INDEX('SL bán theo ngày'!AI$9:AI$82,ROWS($A$11:$A13)),"")} | AG13: {=IF(ROWS($A$11:$A13)<=COUNTIF('SL bán theo ngày'!$A$9:$A$82,"?*"),INDEX('SL bán theo ngày'!C$9:C$82,ROWS($A$11:$A13)),"")} -> Bịch | AH13: {=IF(ROWS($A$11:$A13)<=COUNTIF('SL bán theo ngày'!$A$9:$A$82,"?*"),INDEX('SL bán theo ngày'!D$9:D$82,ROWS($A$11:$A13)),"")} -> 15248 | AI13: {=IF(ROWS($A$11:$A13)<=COUNTIF('SL bán theo ngày'!$A$9:$A$82,"?*"),INDEX('SL bán theo ngày'!E$9:E$82,ROWS($A$11:$A13)),"")} -> 280 | AJ13: {=IF(ROWS($A$11:$A13)<=COUNTIF('SL bán theo ngày'!$A$9:$A$82,"?*"),INDEX('SL bán theo ngày'!AJ$9:AJ$82,ROWS($A$11:$A13)),"")} -> 265 | AK13: {=IF(ROWS($A$11:$A13)<=COUNTIF('SL bán theo ngày'!$A$9:$A$82,"?*"),INDEX('SL bán theo ngày'!AK$9:AK$82,ROWS($A$11:$A13)),"")} -> 15
A14: {=IF(ROWS($A$11:$A14)<=COUNTIF('SL bán theo ngày'!$A$9:$A$82,"?*"),INDEX('SL bán theo ngày'!A$9:A$82,ROWS($A$11:$A14)),"")} -> VP26_10 | B14: {=IF(ROWS($A$11:$A14)<=COUNTIF('SL bán theo ngày'!$A$9:$A$82,"?*"),INDEX('SL bán theo ngày'!B$9:B$82,ROWS($A$11:$A14)),"")} -> Bánh snack Oishi 5K (8 bịch/bao) | C14: {=IF(ROWS($A$11:$A14)<=COUNTIF('SL bán theo ngày'!$A$9:$A$82,"?*"),INDEX('SL bán theo ngày'!F$9:F$82,ROWS($A$11:$A14)),"")} -> 1 | D14: {=IF(ROWS($A$11:$A14)<=COUNTIF('SL bán theo ngày'!$A$9:$A$82,"?*"),INDEX('SL bán theo ngày'!G$9:G$82,ROWS($A$11:$A14)),"")} -> 2 | E14: {=IF(ROWS($A$11:$A14)<=COUNTIF('SL bán theo ngày'!$A$9:$A$82,"?*"),INDEX('SL bán theo ngày'!H$9:H$82,ROWS($A$11:$A14)),"")} -> 1 | F14: {=IF(ROWS($A$11:$A14)<=COUNTIF('SL bán theo ngày'!$A$9:$A$82,"?*"),INDEX('SL bán theo ngày'!I$9:I$82,ROWS($A$11:$A14)),"")} -> 2 | G14: {=IF(ROWS($A$11:$A14)<=COUNTIF('SL bán theo ngày'!$A$9:$A$82,"?*"),INDEX('SL bán theo ngày'!J$9:J$82,ROWS($A$11:$A14)),"")} -> 1 | H14: {=IF(ROWS($A$11:$A14)<=COUNTIF('SL bán theo ngày'!$A$9:$A$82,"?*"),INDEX('SL bán theo ngày'!K$9:K$82,ROWS($A$11:$A14)),"")} | I14: {=IF(ROWS($A$11:$A14)<=COUNTIF('SL bán theo ngày'!$A$9:$A$82,"?*"),INDEX('SL bán theo ngày'!L$9:L$82,ROWS($A$11:$A14)),"")} | J14: {=IF(ROWS($A$11:$A14)<=COUNTIF('SL bán theo ngày'!$A$9:$A$82,"?*"),INDEX('SL bán theo ngày'!M$9:M$82,ROWS($A$11:$A14)),"")} | ... AF14: {=IF(ROWS($A$11:$A14)<=COUNTIF('SL bán theo ngày'!$A$9:$A$82,"?*"),INDEX('SL bán theo ngày'!AI$9:AI$82,ROWS($A$11:$A14)),"")} | AG14: {=IF(ROWS($A$11:$A14)<=COUNTIF('SL bán theo ngày'!$A$9:$A$82,"?*"),INDEX('SL bán theo ngày'!C$9:C$82,ROWS($A$11:$A14)),"")} -> Bịch | AH14: {=IF(ROWS($A$11:$A14)<=COUNTIF('SL bán theo ngày'!$A$9:$A$82,"?*"),INDEX('SL bán theo ngày'!D$9:D$82,ROWS($A$11:$A14)),"")} -> 38500 | AI14: {=IF(ROWS($A$11:$A14)<=COUNTIF('SL bán theo ngày'!$A$9:$A$82,"?*"),INDEX('SL bán theo ngày'!E$9:E$82,ROWS($A$11:$A14)),"")} -> 8 | AJ14: {=IF(ROWS($A$11:$A14)<=COUNTIF('SL bán theo ngày'!$A$9:$A$82,"?*"),INDEX('SL bán theo ngày'!AJ$9:AJ$82,ROWS($A$11:$A14)),"")} -> 7 | AK14: {=IF(ROWS($A$11:$A14)<=COUNTIF('SL bán theo ngày'!$A$9:$A$82,"?*"),INDEX('SL bán theo ngày'!AK$9:AK$82,ROWS($A$11:$A14)),"")} -> 1
A15: {=IF(ROWS($A$11:$A15)<=COUNTIF('SL bán theo ngày'!$A$9:$A$82,"?*"),INDEX('SL bán theo ngày'!A$9:A$82,ROWS($A$11:$A15)),"")} -> VP26_13 | B15: {=IF(ROWS($A$11:$A15)<=COUNTIF('SL bán theo ngày'!$A$9:$A$82,"?*"),INDEX('SL bán theo ngày'!B$9:B$82,ROWS($A$11:$A15)),"")} -> Bánh Chấm 330g PC (12 cái) | C15: {=IF(ROWS($A$11:$A15)<=COUNTIF('SL bán theo ngày'!$A$9:$A$82,"?*"),INDEX('SL bán theo ngày'!F$9:F$82,ROWS($A$11:$A15)),"")} -> 23 | D15: {=IF(ROWS($A$11:$A15)<=COUNTIF('SL bán theo ngày'!$A$9:$A$82,"?*"),INDEX('SL bán theo ngày'!G$9:G$82,ROWS($A$11:$A15)),"")} -> 22 | E15: {=IF(ROWS($A$11:$A15)<=COUNTIF('SL bán theo ngày'!$A$9:$A$82,"?*"),INDEX('SL bán theo ngày'!H$9:H$82,ROWS($A$11:$A15)),"")} -> 22 | F15: {=IF(ROWS($A$11:$A15)<=COUNTIF('SL bán theo ngày'!$A$9:$A$82,"?*"),INDEX('SL bán theo ngày'!I$9:I$82,ROWS($A$11:$A15)),"")} -> 23 | G15: {=IF(ROWS($A$11:$A15)<=COUNTIF('SL bán theo ngày'!$A$9:$A$82,"?*"),INDEX('SL bán theo ngày'!J$9:J$82,ROWS($A$11:$A15)),"")} -> 22 | H15: {=IF(ROWS($A$11:$A15)<=COUNTIF('SL bán theo ngày'!$A$9:$A$82,"?*"),INDEX('SL bán theo ngày'!K$9:K$82,ROWS($A$11:$A15)),"")} | I15: {=IF(ROWS($A$11:$A15)<=COUNTIF('SL bán theo ngày'!$A$9:$A$82,"?*"),INDEX('SL bán theo ngày'!L$9:L$82,ROWS($A$11:$A15)),"")} | J15: {=IF(ROWS($A$11:$A15)<=COUNTIF('SL bán theo ngày'!$A$9:$A$82,"?*"),INDEX('SL bán theo ngày'!M$9:M$82,ROWS($A$11:$A15)),"")} | ... AF15: {=IF(ROWS($A$11:$A15)<=COUNTIF('SL bán theo ngày'!$A$9:$A$82,"?*"),INDEX('SL bán theo ngày'!AI$9:AI$82,ROWS($A$11:$A15)),"")} | AG15: {=IF(ROWS($A$11:$A15)<=COUNTIF('SL bán theo ngày'!$A$9:$A$82,"?*"),INDEX('SL bán theo ngày'!C$9:C$82,ROWS($A$11:$A15)),"")} -> Cái | AH15: {=IF(ROWS($A$11:$A15)<=COUNTIF('SL bán theo ngày'!$A$9:$A$82,"?*"),INDEX('SL bán theo ngày'!D$9:D$82,ROWS($A$11:$A15)),"")} -> 2383 | AI15: {=IF(ROWS($A$11:$A15)<=COUNTIF('SL bán theo ngày'!$A$9:$A$82,"?*"),INDEX('SL bán theo ngày'!E$9:E$82,ROWS($A$11:$A15)),"")} -> 120 | AJ15: {=IF(ROWS($A$11:$A15)<=COUNTIF('SL bán theo ngày'!$A$9:$A$82,"?*"),INDEX('SL bán theo ngày'!AJ$9:AJ$82,ROWS($A$11:$A15)),"")} -> 112 | AK15: {=IF(ROWS($A$11:$A15)<=COUNTIF('SL bán theo ngày'!$A$9:$A$82,"?*"),INDEX('SL bán theo ngày'!AK$9:AK$82,ROWS($A$11:$A15)),"")} -> 8
A16: {=IF(ROWS($A$11:$A16)<=COUNTIF('SL bán theo ngày'!$A$9:$A$82,"?*"),INDEX('SL bán theo ngày'!A$9:A$82,ROWS($A$11:$A16)),"")} -> VP26_32 | B16: {=IF(ROWS($A$11:$A16)<=COUNTIF('SL bán theo ngày'!$A$9:$A$82,"?*"),INDEX('SL bán theo ngày'!B$9:B$82,ROWS($A$11:$A16)),"")} -> Thạch miếng nhỏ Suso LƯỚI 800g (62 cái) | C16: {=IF(ROWS($A$11:$A16)<=COUNTIF('SL bán theo ngày'!$A$9:$A$82,"?*"),INDEX('SL bán theo ngày'!F$9:F$82,ROWS($A$11:$A16)),"")} -> 71 | D16: {=IF(ROWS($A$11:$A16)<=COUNTIF('SL bán theo ngày'!$A$9:$A$82,"?*"),INDEX('SL bán theo ngày'!G$9:G$82,ROWS($A$11:$A16)),"")} -> 70 | E16: {=IF(ROWS($A$11:$A16)<=COUNTIF('SL bán theo ngày'!$A$9:$A$82,"?*"),INDEX('SL bán theo ngày'!H$9:H$82,ROWS($A$11:$A16)),"")} -> 70 | F16: {=IF(ROWS($A$11:$A16)<=COUNTIF('SL bán theo ngày'!$A$9:$A$82,"?*"),INDEX('SL bán theo ngày'!I$9:I$82,ROWS($A$11:$A16)),"")} -> 70 | G16: {=IF(ROWS($A$11:$A16)<=COUNTIF('SL bán theo ngày'!$A$9:$A$82,"?*"),INDEX('SL bán theo ngày'!J$9:J$82,ROWS($A$11:$A16)),"")} -> 70 | H16: {=IF(ROWS($A$11:$A16)<=COUNTIF('SL bán theo ngày'!$A$9:$A$82,"?*"),INDEX('SL bán theo ngày'!K$9:K$82,ROWS($A$11:$A16)),"")} | I16: {=IF(ROWS($A$11:$A16)<=COUNTIF('SL bán theo ngày'!$A$9:$A$82,"?*"),INDEX('SL bán theo ngày'!L$9:L$82,ROWS($A$11:$A16)),"")} | J16: {=IF(ROWS($A$11:$A16)<=COUNTIF('SL bán theo ngày'!$A$9:$A$82,"?*"),INDEX('SL bán theo ngày'!M$9:M$82,ROWS($A$11:$A16)),"")} | ... AF16: {=IF(ROWS($A$11:$A16)<=COUNTIF('SL bán theo ngày'!$A$9:$A$82,"?*"),INDEX('SL bán theo ngày'!AI$9:AI$82,ROWS($A$11:$A16)),"")} | AG16: {=IF(ROWS($A$11:$A16)<=COUNTIF('SL bán theo ngày'!$A$9:$A$82,"?*"),INDEX('SL bán theo ngày'!C$9:C$82,ROWS($A$11:$A16)),"")} -> Cái | AH16: {=IF(ROWS($A$11:$A16)<=COUNTIF('SL bán theo ngày'!$A$9:$A$82,"?*"),INDEX('SL bán theo ngày'!D$9:D$82,ROWS($A$11:$A16)),"")} -> 550 | AI16: {=IF(ROWS($A$11:$A16)<=COUNTIF('SL bán theo ngày'!$A$9:$A$82,"?*"),INDEX('SL bán theo ngày'!E$9:E$82,ROWS($A$11:$A16)),"")} -> 372 | AJ16: {=IF(ROWS($A$11:$A16)<=COUNTIF('SL bán theo ngày'!$A$9:$A$82,"?*"),INDEX('SL bán theo ngày'!AJ$9:AJ$82,ROWS($A$11:$A16)),"")} -> 351 | AK16: {=IF(ROWS($A$11:$A16)<=COUNTIF('SL bán theo ngày'!$A$9:$A$82,"?*"),INDEX('SL bán theo ngày'!AK$9:AK$82,ROWS($A$11:$A16)),"")} -> 21
A17: {=IF(ROWS($A$11:$A17)<=COUNTIF('SL bán theo ngày'!$A$9:$A$82,"?*"),INDEX('SL bán theo ngày'!A$9:A$82,ROWS($A$11:$A17)),"")} -> VP26_40 | B17: {=IF(ROWS($A$11:$A17)<=COUNTIF('SL bán theo ngày'!$A$9:$A$82,"?*"),INDEX('SL bán theo ngày'!B$9:B$82,ROWS($A$11:$A17)),"")} -> Coke 300ml - Coca Chai Nhí 5K | C17: {=IF(ROWS($A$11:$A17)<=COUNTIF('SL bán theo ngày'!$A$9:$A$82,"?*"),INDEX('SL bán theo ngày'!F$9:F$82,ROWS($A$11:$A17)),"")} -> 4 | D17: {=IF(ROWS($A$11:$A17)<=COUNTIF('SL bán theo ngày'!$A$9:$A$82,"?*"),INDEX('SL bán theo ngày'!G$9:G$82,ROWS($A$11:$A17)),"")} -> 5 | E17: {=IF(ROWS($A$11:$A17)<=COUNTIF('SL bán theo ngày'!$A$9:$A$82,"?*"),INDEX('SL bán theo ngày'!H$9:H$82,ROWS($A$11:$A17)),"")} -> 4 | F17: {=IF(ROWS($A$11:$A17)<=COUNTIF('SL bán theo ngày'!$A$9:$A$82,"?*"),INDEX('SL bán theo ngày'!I$9:I$82,ROWS($A$11:$A17)),"")} -> 5 | G17: {=IF(ROWS($A$11:$A17)<=COUNTIF('SL bán theo ngày'!$A$9:$A$82,"?*"),INDEX('SL bán theo ngày'!J$9:J$82,ROWS($A$11:$A17)),"")} -> 4 | H17: {=IF(ROWS($A$11:$A17)<=COUNTIF('SL bán theo ngày'!$A$9:$A$82,"?*"),INDEX('SL bán theo ngày'!K$9:K$82,ROWS($A$11:$A17)),"")} | I17: {=IF(ROWS($A$11:$A17)<=COUNTIF('SL bán theo ngày'!$A$9:$A$82,"?*"),INDEX('SL bán theo ngày'!L$9:L$82,ROWS($A$11:$A17)),"")} | J17: {=IF(ROWS($A$11:$A17)<=COUNTIF('SL bán theo ngày'!$A$9:$A$82,"?*"),INDEX('SL bán theo ngày'!M$9:M$82,ROWS($A$11:$A17)),"")} | ... AF17: {=IF(ROWS($A$11:$A17)<=COUNTIF('SL bán theo ngày'!$A$9:$A$82,"?*"),INDEX('SL bán theo ngày'!AI$9:AI$82,ROWS($A$11:$A17)),"")} | AG17: {=IF(ROWS($A$11:$A17)<=COUNTIF('SL bán theo ngày'!$A$9:$A$82,"?*"),INDEX('SL bán theo ngày'!C$9:C$82,ROWS($A$11:$A17)),"")} -> Chai | AH17: {=IF(ROWS($A$11:$A17)<=COUNTIF('SL bán theo ngày'!$A$9:$A$82,"?*"),INDEX('SL bán theo ngày'!D$9:D$82,ROWS($A$11:$A17)),"")} -> 4285 | AI17: {=IF(ROWS($A$11:$A17)<=COUNTIF('SL bán theo ngày'!$A$9:$A$82,"?*"),INDEX('SL bán theo ngày'!E$9:E$82,ROWS($A$11:$A17)),"")} -> 24 | AJ17: {=IF(ROWS($A$11:$A17)<=COUNTIF('SL bán theo ngày'!$A$9:$A$82,"?*"),INDEX('SL bán theo ngày'!AJ$9:AJ$82,ROWS($A$11:$A17)),"")} -> 22 | AK17: {=IF(ROWS($A$11:$A17)<=COUNTIF('SL bán theo ngày'!$A$9:$A$82,"?*"),INDEX('SL bán theo ngày'!AK$9:AK$82,ROWS($A$11:$A17)),"")} -> 2
A18: {=IF(ROWS($A$11:$A18)<=COUNTIF('SL bán theo ngày'!$A$9:$A$82,"?*"),INDEX('SL bán theo ngày'!A$9:A$82,ROWS($A$11:$A18)),"")} -> VP26_41 | B18: {=IF(ROWS($A$11:$A18)<=COUNTIF('SL bán theo ngày'!$A$9:$A$82,"?*"),INDEX('SL bán theo ngày'!B$9:B$82,ROWS($A$11:$A18)),"")} -> Đậu phộng Oishi 1K (20 dây/T) | C18: {=IF(ROWS($A$11:$A18)<=COUNTIF('SL bán theo ngày'!$A$9:$A$82,"?*"),INDEX('SL bán theo ngày'!F$9:F$82,ROWS($A$11:$A18)),"")} -> 4 | D18: {=IF(ROWS($A$11:$A18)<=COUNTIF('SL bán theo ngày'!$A$9:$A$82,"?*"),INDEX('SL bán theo ngày'!G$9:G$82,ROWS($A$11:$A18)),"")} -> 3 | E18: {=IF(ROWS($A$11:$A18)<=COUNTIF('SL bán theo ngày'!$A$9:$A$82,"?*"),INDEX('SL bán theo ngày'!H$9:H$82,ROWS($A$11:$A18)),"")} -> 4 | F18: {=IF(ROWS($A$11:$A18)<=COUNTIF('SL bán theo ngày'!$A$9:$A$82,"?*"),INDEX('SL bán theo ngày'!I$9:I$82,ROWS($A$11:$A18)),"")} -> 3 | G18: {=IF(ROWS($A$11:$A18)<=COUNTIF('SL bán theo ngày'!$A$9:$A$82,"?*"),INDEX('SL bán theo ngày'!J$9:J$82,ROWS($A$11:$A18)),"")} -> 4 | H18: {=IF(ROWS($A$11:$A18)<=COUNTIF('SL bán theo ngày'!$A$9:$A$82,"?*"),INDEX('SL bán theo ngày'!K$9:K$82,ROWS($A$11:$A18)),"")} | I18: {=IF(ROWS($A$11:$A18)<=COUNTIF('SL bán theo ngày'!$A$9:$A$82,"?*"),INDEX('SL bán theo ngày'!L$9:L$82,ROWS($A$11:$A18)),"")} | J18: {=IF(ROWS($A$11:$A18)<=COUNTIF('SL bán theo ngày'!$A$9:$A$82,"?*"),INDEX('SL bán theo ngày'!M$9:M$82,ROWS($A$11:$A18)),"")} | ... AF18: {=IF(ROWS($A$11:$A18)<=COUNTIF('SL bán theo ngày'!$A$9:$A$82,"?*"),INDEX('SL bán theo ngày'!AI$9:AI$82,ROWS($A$11:$A18)),"")} | AG18: {=IF(ROWS($A$11:$A18)<=COUNTIF('SL bán theo ngày'!$A$9:$A$82,"?*"),INDEX('SL bán theo ngày'!C$9:C$82,ROWS($A$11:$A18)),"")} -> Dây | AH18: {=IF(ROWS($A$11:$A18)<=COUNTIF('SL bán theo ngày'!$A$9:$A$82,"?*"),INDEX('SL bán theo ngày'!D$9:D$82,ROWS($A$11:$A18)),"")} -> 7637 | AI18: {=IF(ROWS($A$11:$A18)<=COUNTIF('SL bán theo ngày'!$A$9:$A$82,"?*"),INDEX('SL bán theo ngày'!E$9:E$82,ROWS($A$11:$A18)),"")} -> 20 | AJ18: {=IF(ROWS($A$11:$A18)<=COUNTIF('SL bán theo ngày'!$A$9:$A$82,"?*"),INDEX('SL bán theo ngày'!AJ$9:AJ$82,ROWS($A$11:$A18)),"")} -> 18 | AK18: {=IF(ROWS($A$11:$A18)<=COUNTIF('SL bán theo ngày'!$A$9:$A$82,"?*"),INDEX('SL bán theo ngày'!AK$9:AK$82,ROWS($A$11:$A18)),"")} -> 2
A19: {=IF(ROWS($A$11:$A19)<=COUNTIF('SL bán theo ngày'!$A$9:$A$82,"?*"),INDEX('SL bán theo ngày'!A$9:A$82,ROWS($A$11:$A19)),"")} -> VP26_43 | B19: {=IF(ROWS($A$11:$A19)<=COUNTIF('SL bán theo ngày'!$A$9:$A$82,"?*"),INDEX('SL bán theo ngày'!B$9:B$82,ROWS($A$11:$A19)),"")} -> Thạch SUSO Cây Dài (24 cái) | C19: {=IF(ROWS($A$11:$A19)<=COUNTIF('SL bán theo ngày'!$A$9:$A$82,"?*"),INDEX('SL bán theo ngày'!F$9:F$82,ROWS($A$11:$A19)),"")} -> 81 | D19: {=IF(ROWS($A$11:$A19)<=COUNTIF('SL bán theo ngày'!$A$9:$A$82,"?*"),INDEX('SL bán theo ngày'!G$9:G$82,ROWS($A$11:$A19)),"")} -> 81 | E19: {=IF(ROWS($A$11:$A19)<=COUNTIF('SL bán theo ngày'!$A$9:$A$82,"?*"),INDEX('SL bán theo ngày'!H$9:H$82,ROWS($A$11:$A19)),"")} -> 82 | F19: {=IF(ROWS($A$11:$A19)<=COUNTIF('SL bán theo ngày'!$A$9:$A$82,"?*"),INDEX('SL bán theo ngày'!I$9:I$82,ROWS($A$11:$A19)),"")} -> 81 | G19: {=IF(ROWS($A$11:$A19)<=COUNTIF('SL bán theo ngày'!$A$9:$A$82,"?*"),INDEX('SL bán theo ngày'!J$9:J$82,ROWS($A$11:$A19)),"")} -> 81 | H19: {=IF(ROWS($A$11:$A19)<=COUNTIF('SL bán theo ngày'!$A$9:$A$82,"?*"),INDEX('SL bán theo ngày'!K$9:K$82,ROWS($A$11:$A19)),"")} | I19: {=IF(ROWS($A$11:$A19)<=COUNTIF('SL bán theo ngày'!$A$9:$A$82,"?*"),INDEX('SL bán theo ngày'!L$9:L$82,ROWS($A$11:$A19)),"")} | J19: {=IF(ROWS($A$11:$A19)<=COUNTIF('SL bán theo ngày'!$A$9:$A$82,"?*"),INDEX('SL bán theo ngày'!M$9:M$82,ROWS($A$11:$A19)),"")} | ... AF19: {=IF(ROWS($A$11:$A19)<=COUNTIF('SL bán theo ngày'!$A$9:$A$82,"?*"),INDEX('SL bán theo ngày'!AI$9:AI$82,ROWS($A$11:$A19)),"")} | AG19: {=IF(ROWS($A$11:$A19)<=COUNTIF('SL bán theo ngày'!$A$9:$A$82,"?*"),INDEX('SL bán theo ngày'!C$9:C$82,ROWS($A$11:$A19)),"")} -> Cái | AH19: {=IF(ROWS($A$11:$A19)<=COUNTIF('SL bán theo ngày'!$A$9:$A$82,"?*"),INDEX('SL bán theo ngày'!D$9:D$82,ROWS($A$11:$A19)),"")} -> 1375 | AI19: {=IF(ROWS($A$11:$A19)<=COUNTIF('SL bán theo ngày'!$A$9:$A$82,"?*"),INDEX('SL bán theo ngày'!E$9:E$82,ROWS($A$11:$A19)),"")} -> 432 | AJ19: {=IF(ROWS($A$11:$A19)<=COUNTIF('SL bán theo ngày'!$A$9:$A$82,"?*"),INDEX('SL bán theo ngày'!AJ$9:AJ$82,ROWS($A$11:$A19)),"")} -> 406 | AK19: {=IF(ROWS($A$11:$A19)<=COUNTIF('SL bán theo ngày'!$A$9:$A$82,"?*"),INDEX('SL bán theo ngày'!AK$9:AK$82,ROWS($A$11:$A19)),"")} -> 26
A20: {=IF(ROWS($A$11:$A20)<=COUNTIF('SL bán theo ngày'!$A$9:$A$82,"?*"),INDEX('SL bán theo ngày'!A$9:A$82,ROWS($A$11:$A20)),"")} -> VP26_45 | B20: {=IF(ROWS($A$11:$A20)<=COUNTIF('SL bán theo ngày'!$A$9:$A$82,"?*"),INDEX('SL bán theo ngày'!B$9:B$82,ROWS($A$11:$A20)),"")} -> Mì Vàng Enaak 30g (24 gói/Hộp) | C20: {=IF(ROWS($A$11:$A20)<=COUNTIF('SL bán theo ngày'!$A$9:$A$82,"?*"),INDEX('SL bán theo ngày'!F$9:F$82,ROWS($A$11:$A20)),"")} -> 27 | D20: {=IF(ROWS($A$11:$A20)<=COUNTIF('SL bán theo ngày'!$A$9:$A$82,"?*"),INDEX('SL bán theo ngày'!G$9:G$82,ROWS($A$11:$A20)),"")} -> 27 | E20: {=IF(ROWS($A$11:$A20)<=COUNTIF('SL bán theo ngày'!$A$9:$A$82,"?*"),INDEX('SL bán theo ngày'!H$9:H$82,ROWS($A$11:$A20)),"")} -> 27 | F20: {=IF(ROWS($A$11:$A20)<=COUNTIF('SL bán theo ngày'!$A$9:$A$82,"?*"),INDEX('SL bán theo ngày'!I$9:I$82,ROWS($A$11:$A20)),"")} -> 27 | G20: {=IF(ROWS($A$11:$A20)<=COUNTIF('SL bán theo ngày'!$A$9:$A$82,"?*"),INDEX('SL bán theo ngày'!J$9:J$82,ROWS($A$11:$A20)),"")} -> 27 | H20: {=IF(ROWS($A$11:$A20)<=COUNTIF('SL bán theo ngày'!$A$9:$A$82,"?*"),INDEX('SL bán theo ngày'!K$9:K$82,ROWS($A$11:$A20)),"")} | I20: {=IF(ROWS($A$11:$A20)<=COUNTIF('SL bán theo ngày'!$A$9:$A$82,"?*"),INDEX('SL bán theo ngày'!L$9:L$82,ROWS($A$11:$A20)),"")} | J20: {=IF(ROWS($A$11:$A20)<=COUNTIF('SL bán theo ngày'!$A$9:$A$82,"?*"),INDEX('SL bán theo ngày'!M$9:M$82,ROWS($A$11:$A20)),"")} | ... AF20: {=IF(ROWS($A$11:$A20)<=COUNTIF('SL bán theo ngày'!$A$9:$A$82,"?*"),INDEX('SL bán theo ngày'!AI$9:AI$82,ROWS($A$11:$A20)),"")} | AG20: {=IF(ROWS($A$11:$A20)<=COUNTIF('SL bán theo ngày'!$A$9:$A$82,"?*"),INDEX('SL bán theo ngày'!C$9:C$82,ROWS($A$11:$A20)),"")} -> Gói | AH20: {=IF(ROWS($A$11:$A20)<=COUNTIF('SL bán theo ngày'!$A$9:$A$82,"?*"),INDEX('SL bán theo ngày'!D$9:D$82,ROWS($A$11:$A20)),"")} -> 5500 | AI20: {=IF(ROWS($A$11:$A20)<=COUNTIF('SL bán theo ngày'!$A$9:$A$82,"?*"),INDEX('SL bán theo ngày'!E$9:E$82,ROWS($A$11:$A20)),"")} -> 144 | AJ20: {=IF(ROWS($A$11:$A20)<=COUNTIF('SL bán theo ngày'!$A$9:$A$82,"?*"),INDEX('SL bán theo ngày'!AJ$9:AJ$82,ROWS($A$11:$A20)),"")} -> 135 | AK20: {=IF(ROWS($A$11:$A20)<=COUNTIF('SL bán theo ngày'!$A$9:$A$82,"?*"),INDEX('SL bán theo ngày'!AK$9:AK$82,ROWS($A$11:$A20)),"")} -> 9
A21: {=IF(ROWS($A$11:$A21)<=COUNTIF('SL bán theo ngày'!$A$9:$A$82,"?*"),INDEX('SL bán theo ngày'!A$9:A$82,ROWS($A$11:$A21)),"")} -> VP26_46 | B21: {=IF(ROWS($A$11:$A21)<=COUNTIF('SL bán theo ngày'!$A$9:$A$82,"?*"),INDEX('SL bán theo ngày'!B$9:B$82,ROWS($A$11:$A21)),"")} -> Nước ÉP THẠCH Suso (48 ly) | C21: {=IF(ROWS($A$11:$A21)<=COUNTIF('SL bán theo ngày'!$A$9:$A$82,"?*"),INDEX('SL bán theo ngày'!F$9:F$82,ROWS($A$11:$A21)),"")} -> 90 | D21: {=IF(ROWS($A$11:$A21)<=COUNTIF('SL bán theo ngày'!$A$9:$A$82,"?*"),INDEX('SL bán theo ngày'!G$9:G$82,ROWS($A$11:$A21)),"")} -> 91 | E21: {=IF(ROWS($A$11:$A21)<=COUNTIF('SL bán theo ngày'!$A$9:$A$82,"?*"),INDEX('SL bán theo ngày'!H$9:H$82,ROWS($A$11:$A21)),"")} -> 90 | F21: {=IF(ROWS($A$11:$A21)<=COUNTIF('SL bán theo ngày'!$A$9:$A$82,"?*"),INDEX('SL bán theo ngày'!I$9:I$82,ROWS($A$11:$A21)),"")} -> 90 | G21: {=IF(ROWS($A$11:$A21)<=COUNTIF('SL bán theo ngày'!$A$9:$A$82,"?*"),INDEX('SL bán theo ngày'!J$9:J$82,ROWS($A$11:$A21)),"")} -> 90 | H21: {=IF(ROWS($A$11:$A21)<=COUNTIF('SL bán theo ngày'!$A$9:$A$82,"?*"),INDEX('SL bán theo ngày'!K$9:K$82,ROWS($A$11:$A21)),"")} | I21: {=IF(ROWS($A$11:$A21)<=COUNTIF('SL bán theo ngày'!$A$9:$A$82,"?*"),INDEX('SL bán theo ngày'!L$9:L$82,ROWS($A$11:$A21)),"")} | J21: {=IF(ROWS($A$11:$A21)<=COUNTIF('SL bán theo ngày'!$A$9:$A$82,"?*"),INDEX('SL bán theo ngày'!M$9:M$82,ROWS($A$11:$A21)),"")} | ... AF21: {=IF(ROWS($A$11:$A21)<=COUNTIF('SL bán theo ngày'!$A$9:$A$82,"?*"),INDEX('SL bán theo ngày'!AI$9:AI$82,ROWS($A$11:$A21)),"")} | AG21: {=IF(ROWS($A$11:$A21)<=COUNTIF('SL bán theo ngày'!$A$9:$A$82,"?*"),INDEX('SL bán theo ngày'!C$9:C$82,ROWS($A$11:$A21)),"")} -> Ly | AH21: {=IF(ROWS($A$11:$A21)<=COUNTIF('SL bán theo ngày'!$A$9:$A$82,"?*"),INDEX('SL bán theo ngày'!D$9:D$82,ROWS($A$11:$A21)),"")} -> 3942 | AI21: {=IF(ROWS($A$11:$A21)<=COUNTIF('SL bán theo ngày'!$A$9:$A$82,"?*"),INDEX('SL bán theo ngày'!E$9:E$82,ROWS($A$11:$A21)),"")} -> 480 | AJ21: {=IF(ROWS($A$11:$A21)<=COUNTIF('SL bán theo ngày'!$A$9:$A$82,"?*"),INDEX('SL bán theo ngày'!AJ$9:AJ$82,ROWS($A$11:$A21)),"")} -> 451 | AK21: {=IF(ROWS($A$11:$A21)<=COUNTIF('SL bán theo ngày'!$A$9:$A$82,"?*"),INDEX('SL bán theo ngày'!AK$9:AK$82,ROWS($A$11:$A21)),"")} -> 29
A22: {=IF(ROWS($A$11:$A22)<=COUNTIF('SL bán theo ngày'!$A$9:$A$82,"?*"),INDEX('SL bán theo ngày'!A$9:A$82,ROWS($A$11:$A22)),"")} -> VP26_47 | B22: {=IF(ROWS($A$11:$A22)<=COUNTIF('SL bán theo ngày'!$A$9:$A$82,"?*"),INDEX('SL bán theo ngày'!B$9:B$82,ROWS($A$11:$A22)),"")} -> Kẹo Cao Su Dinos 500g (69 viên) | C22: {=IF(ROWS($A$11:$A22)<=COUNTIF('SL bán theo ngày'!$A$9:$A$82,"?*"),INDEX('SL bán theo ngày'!F$9:F$82,ROWS($A$11:$A22)),"")} -> 143 | D22: {=IF(ROWS($A$11:$A22)<=COUNTIF('SL bán theo ngày'!$A$9:$A$82,"?*"),INDEX('SL bán theo ngày'!G$9:G$82,ROWS($A$11:$A22)),"")} -> 144 | E22: {=IF(ROWS($A$11:$A22)<=COUNTIF('SL bán theo ngày'!$A$9:$A$82,"?*"),INDEX('SL bán theo ngày'!H$9:H$82,ROWS($A$11:$A22)),"")} -> 143 | F22: {=IF(ROWS($A$11:$A22)<=COUNTIF('SL bán theo ngày'!$A$9:$A$82,"?*"),INDEX('SL bán theo ngày'!I$9:I$82,ROWS($A$11:$A22)),"")} -> 142 | G22: {=IF(ROWS($A$11:$A22)<=COUNTIF('SL bán theo ngày'!$A$9:$A$82,"?*"),INDEX('SL bán theo ngày'!J$9:J$82,ROWS($A$11:$A22)),"")} -> 141 | H22: {=IF(ROWS($A$11:$A22)<=COUNTIF('SL bán theo ngày'!$A$9:$A$82,"?*"),INDEX('SL bán theo ngày'!K$9:K$82,ROWS($A$11:$A22)),"")} | I22: {=IF(ROWS($A$11:$A22)<=COUNTIF('SL bán theo ngày'!$A$9:$A$82,"?*"),INDEX('SL bán theo ngày'!L$9:L$82,ROWS($A$11:$A22)),"")} | J22: {=IF(ROWS($A$11:$A22)<=COUNTIF('SL bán theo ngày'!$A$9:$A$82,"?*"),INDEX('SL bán theo ngày'!M$9:M$82,ROWS($A$11:$A22)),"")} | ... AF22: {=IF(ROWS($A$11:$A22)<=COUNTIF('SL bán theo ngày'!$A$9:$A$82,"?*"),INDEX('SL bán theo ngày'!AI$9:AI$82,ROWS($A$11:$A22)),"")} | AG22: {=IF(ROWS($A$11:$A22)<=COUNTIF('SL bán theo ngày'!$A$9:$A$82,"?*"),INDEX('SL bán theo ngày'!C$9:C$82,ROWS($A$11:$A22)),"")} -> Viên | AH22: {=IF(ROWS($A$11:$A22)<=COUNTIF('SL bán theo ngày'!$A$9:$A$82,"?*"),INDEX('SL bán theo ngày'!D$9:D$82,ROWS($A$11:$A22)),"")} -> 829 | AI22: {=IF(ROWS($A$11:$A22)<=COUNTIF('SL bán theo ngày'!$A$9:$A$82,"?*"),INDEX('SL bán theo ngày'!E$9:E$82,ROWS($A$11:$A22)),"")} -> 759 | AJ22: {=IF(ROWS($A$11:$A22)<=COUNTIF('SL bán theo ngày'!$A$9:$A$82,"?*"),INDEX('SL bán theo ngày'!AJ$9:AJ$82,ROWS($A$11:$A22)),"")} -> 713 | AK22: {=IF(ROWS($A$11:$A22)<=COUNTIF('SL bán theo ngày'!$A$9:$A$82,"?*"),INDEX('SL bán theo ngày'!AK$9:AK$82,ROWS($A$11:$A22)),"")} -> 46
... A84: {=IF(ROWS($A$11:$A84)<=COUNTIF('SL bán theo ngày'!$A$9:$A$82,"?*"),INDEX('SL bán theo ngày'!A$9:A$82,ROWS($A$11:$A84)),"")} | B84: {=IF(ROWS($A$11:$A84)<=COUNTIF('SL bán theo ngày'!$A$9:$A$82,"?*"),INDEX('SL bán theo ngày'!B$9:B$82,ROWS($A$11:$A84)),"")} | C84: {=IF(ROWS($A$11:$A84)<=COUNTIF('SL bán theo ngày'!$A$9:$A$82,"?*"),INDEX('SL bán theo ngày'!F$9:F$82,ROWS($A$11:$A84)),"")} | D84: {=IF(ROWS($A$11:$A84)<=COUNTIF('SL bán theo ngày'!$A$9:$A$82,"?*"),INDEX('SL bán theo ngày'!G$9:G$82,ROWS($A$11:$A84)),"")} | E84: {=IF(ROWS($A$11:$A84)<=COUNTIF('SL bán theo ngày'!$A$9:$A$82,"?*"),INDEX('SL bán theo ngày'!H$9:H$82,ROWS($A$11:$A84)),"")} | F84: {=IF(ROWS($A$11:$A84)<=COUNTIF('SL bán theo ngày'!$A$9:$A$82,"?*"),INDEX('SL bán theo ngày'!I$9:I$82,ROWS($A$11:$A84)),"")} | G84: {=IF(ROWS($A$11:$A84)<=COUNTIF('SL bán theo ngày'!$A$9:$A$82,"?*"),INDEX('SL bán theo ngày'!J$9:J$82,ROWS($A$11:$A84)),"")} | H84: {=IF(ROWS($A$11:$A84)<=COUNTIF('SL bán theo ngày'!$A$9:$A$82,"?*"),INDEX('SL bán theo ngày'!K$9:K$82,ROWS($A$11:$A84)),"")} | I84: {=IF(ROWS($A$11:$A84)<=COUNTIF('SL bán theo ngày'!$A$9:$A$82,"?*"),INDEX('SL bán theo ngày'!L$9:L$82,ROWS($A$11:$A84)),"")} | J84: {=IF(ROWS($A$11:$A84)<=COUNTIF('SL bán theo ngày'!$A$9:$A$82,"?*"),INDEX('SL bán theo ngày'!M$9:M$82,ROWS($A$11:$A84)),"")} | ... AF84: {=IF(ROWS($A$11:$A84)<=COUNTIF('SL bán theo ngày'!$A$9:$A$82,"?*"),INDEX('SL bán theo ngày'!AI$9:AI$82,ROWS($A$11:$A84)),"")} | AG84: {=IF(ROWS($A$11:$A84)<=COUNTIF('SL bán theo ngày'!$A$9:$A$82,"?*"),INDEX('SL bán theo ngày'!C$9:C$82,ROWS($A$11:$A84)),"")} | AH84: {=IF(ROWS($A$11:$A84)<=COUNTIF('SL bán theo ngày'!$A$9:$A$82,"?*"),INDEX('SL bán theo ngày'!D$9:D$82,ROWS($A$11:$A84)),"")} | AI84: {=IF(ROWS($A$11:$A84)<=COUNTIF('SL bán theo ngày'!$A$9:$A$82,"?*"),INDEX('SL bán theo ngày'!E$9:E$82,ROWS($A$11:$A84)),"")} | AJ84: {=IF(ROWS($A$11:$A84)<=COUNTIF('SL bán theo ngày'!$A$9:$A$82,"?*"),INDEX('SL bán theo ngày'!AJ$9:AJ$82,ROWS($A$11:$A84)),"")} | AK84: {=IF(ROWS($A$11:$A84)<=COUNTIF('SL bán theo ngày'!$A$9:$A$82,"?*"),INDEX('SL bán theo ngày'!AK$9:AK$82,ROWS($A$11:$A84)),"")}

Sheet SL bán theo ngày
A1: CHI TIẾT SỐ LƯỢNG BÁN THEO NGÀY
A2: DOANH THU THÁNG | B2: ='BAO CAO BAN HANG'!B2 -> 11000000 | C2: ĐÃ PHÂN BỔ | D2: =SUM(F86:AI86) -> 10999796 | E2: CHÊNH LỆCH | F2: =D2-B2 -> -204
A3: THÁNG PHÂN BỔ | B3: ='BAO CAO BAN HANG'!B3 -> 5 | C3: BIÊN ĐỘ TỐI ĐA | D3: ='BAO CAO BAN HANG'!E3 -> 0.01 | E3: MÓN/ NGÀY | F3: =IFERROR(__xludf.DUMMYFUNCTION("IFERROR(MIN(FILTER(F84:AI84, F84:AI84>0)), 0)&""–""&MAX(F84:AI84)&"" món"""),"11–13 món") -> 11–13 món
A5: SỐ LOẠI BÁN | E5: =COUNTIF(AJ9:AJ82,">0") -> 14 | H5: =F84 -> 14 | I5: =G84 -> 13 | J5: =H84 -> 13 | K5: =I84 -> 13 | L5: =J84 -> 14 | M5: =K84 -> 0 | N5: =L84 -> 0 | O5: =M84 -> 0 | ... AK5: =AI84 -> 0
A6: TỔNG SL BÁN | E6: =AJ85 -> 2982 | H6: =F85 -> 599 | I6: =G85 -> 598 | J6: =H85 -> 596 | K6: =I85 -> 595 | L6: =J85 -> 594 | M6: =K85 -> 0 | N6: =L85 -> 0 | O6: =M85 -> 0 | ... AK6: =AI85 -> 0
A7: TỔNG TIỀN BÁN | E7: =AJ86 -> 10999796 | H7: =F86 -> 2226118 | I7: =G86 -> 2198669 | J7: =H86 -> 2163150 | K7: =I86 -> 2192892 | L7: =J86 -> 2218967 | M7: =K86 -> 0 | N7: =L86 -> 0 | O7: =M86 -> 0 | ... AK7: =AI86 -> 0
